Workbook
Name DIA: '1ra.COMUNION'!#REF!
Name DIA: CONSTANCIA.BAUTISMO!#REF!
Name DIA: MATRIMONIO!#REF!
Name DIA: MATRIMONIO!#REF!

Sheet MATRIMONIO
B3: CERTIFICADO DE MATRIMONIO
B5: PAREJA | C5: DIA | D5: MES | E5: AÑO | F5: PRESBITERO | G5: TESTIGO1 | H5: TESTIGO2 | I5: TESTIGO3 | J5: TESTIGO4 | K5: PÁRROCO | L5: LIBRO | M5: PAGINA | N5: PARTIDA
A6: 1 | B6: RAUL Y MARIA DEL CARMEN | C6: 20 | D6: SEPTIEMBRE | E6: 2009 | F6: FELIPE DE JESUS ZARAGOZA ORTEGA | K6: PBRO.FELIPE DE JESUS ZARAGOZA ORTEGA | L6: 1 | M6: 1 | N6: 1
A7: 2 | B7: HERIBERTO Y KARLA | C7: 17 | D7: DICIEMBRE | E7: 2010 | F7: FELIPE DE JESUS ZARAGOZA ORTEGA | K7: PBRO.FELIPE DE JESUS ZARAGOZA ORTEGA | L7: 1 | M7: 1 | N7: 2
A8: 3 | B8: ARTURO ALONSO Y VERONICA | C8: 18 | D8: DICIEMBRE | E8: 2010 | F8: FELIPE DE JESUS ZARAGOZA ORTEGA | K8: PBRO.FELIPE DE JESUS ZARAGOZA ORTEGA | L8: 1 | M8: 2 | N8: 3
A9: 4 | B9: HERIBERTO Y CECILIA GUADALUPE | C9: 23 | D9: ABRIL | E9: 2011 | F9: FELIPE DE JESUS ZARAGOZA ORTEGA | K9: PBRO.FELIPE DE JESUS ZARAGOZA ORTEGA | L9: 1 | M9: 2 | N9: 4
A10: 5 | B10: JOSE MANUEL Y BLANCA | C10: 27 | D10: MAYO | E10: 2011 | F10: FELIPE DE JESUS ZARAGOZA ORTEGA | K10: PBRO.FELIPE DE JESUS ZARAGOZA ORTEGA | L10: 1 | M10: 3 | N10: 5
A11: 6 | B11: ANTONIO ENRIQUE Y KATY SUGEY | C11: 17 | D11: SEPTIEMBRE | E11: 2011 | F11: FELIPE DE JESUS ZARAGOZA ORTEGA | G11: LUZ MERCEDES VASQUEZ JAIME | H11: ALFONSO LARIOS SOLORIO | I11: GERARDO COVARRUBIO HIDALGO | J11: ADRIANA NIEBLAS GAXIOLA | K11: PBRO.FELIPE DE JESUS ZARAGOZA ORTEGA | L11: 1 | M11: 3 | N11: 6 | V11: 2 | W11: FEBRERO
A12: 7 | B12: ABRAHAM Y LETICIA | C12: 8 | D12: ENERO | E12: 2012 | F12: FELIPE DE JESUS ZARAGOZA ORTEGA | G12: JOSE GILBERTO MORENO VALENCIA | H12: ROSA MARIA ARANA SALDAÑA | I12: BERNARDINO GARCIA GALLEGOS | J12: LETICIA LEYVA RUIZ | K12: PBRO.FELIPE DE JESUS ZARAGOZA ORTEGA | L12: 1 | M12: 4 | N12: 7 | V12: 3 | W12: MARZO
A13: 8 | B13: ALEJANDRO Y ROMANA | C13: 14 | D13: ABRIL | E13: 2012 | F13: FELIPE DE JESUS ZARAGOZA ORTEGA | K13: PBRO.FELIPE DE JESUS ZARAGOZA ORTEGA | L13: 1 | M13: 4 | N13: 8
A14: 9 | B14: JOSE ANGEL Y ELIZABETH | C14: 27 | D14: JULIO | E14: 2012 | F14: FELIPE DE JESUS ZARAGOZA ORTEGA | G14: MARTHA IMELDA MORALES BABUCA | H14: FCO. ALEJO ROMERO LARES | I14: TERESA VELAZCO CRUZ | J14: MIGUEL ANGEL FLORES MORALES | K14: PBRO.FELIPE DE JESUS ZARAGOZA ORTEGA | L14: 1 | M14: 5 | N14: 9 | V14: 4 | W14: ABRIL
A15: 10 | B15: JESUS MANUEL Y KARLA ALEJANDRA | C15: 8 | D15: SEPTIEMBRE | E15: 2012 | F15: FELIPE DE JESUS ZARAGOZA ORTEGA | G15: MANUEL ANDRES DURAZO HEREDIA | H15: GRACIELA MIRANDA RODRIGUEZ | I15: RODOLFO HEREDIA LOPEZ | J15: MARIA RODRIGUEZ OCHOA | K15: PBRO.FELIPE DE JESUS ZARAGOZA ORTEGA | L15: 1 | M15: 5 | N15: 10 | V15: 5 | W15: MAYO
A16: 11 | B16: JESUS ARSENIO Y MARTHA ELENA | C16: 29 | D16: SEPTIEMBRE | E16: 2012 | F16: FELIPE DE JESUS ZARAGOZA ORTEGA | G16: JOSELINO FERRER BASTIDA | H16: CONSUELO ZARAGOZA PARADA | I16: MA. DEL CARMEN ALVAREZ LEÓN | J16: ROSA DELIA ALVAREZ LEÓN | K16: PBRO.FELIPE DE JESUS ZARAGOZA ORTEGA | L16: 1 | M16: 6 | N16: 11 | V16: 6 | W16: JUNIO
A17: 12 | B17: FRANCISCO ALAN Y DANIAH MARISSA | C17: 17 | D17: NOVIEMBRE | E17: 2012 | F17: FELIPE DE JESUS ZARAGOZA ORTEGA | G17: LUIS GERARDO GARCÍA BERNAL | H17: YARIBEL SEGUAME OCAMPO | I17: DANIELA NAVARRO IBARRA | J17: CHRISTIAN GARCÍA MORENO. | K17: PBRO.FELIPE DE JESUS ZARAGOZA ORTEGA | L17: 1 | M17: 6 | N17: 12 | V17: 7 | W17: JULIO
A18: 13 | B18: LUIS ALFONSO Y ROSA MARIA | C18: 15 | D18: DICIEMBRE | E18: 2012 | F18: RAMON ENCINAS ENCINAS | G18: MIGUEL IGNACIO GUERRERO MARIN | H18: MA. DEL CARMEN DE LA LLATA GARZA | I18: BARBARA LUZ MARTINEZ | J18: ROSA MARIA MARTINEZ | K18: PBRO.FELIPE DE JESUS ZARAGOZA ORTEGA | L18: 1 | M18: 7 | N18: 13 | V18: 8 | W18: AGOSTO
A19: 14 | B19: ARTURO Y MARIA DE LOURDES | C19: 16 | D19: MARZO | E19: 2013 | F19: FELIPE DE JESUS ZARAGOZA ORTEGA | G19: BRENDA LOYA | H19: HORACIO MEZA | I19: DEYANIRA VEGA | J19: ARTURO QUINTERO | K19: PBRO.FELIPE DE JESUS ZARAGOZA ORTEGA | L19: 1 | M19: 7 | N19: 14 | V19: 9 | W19: SEPTIEMBRE
A20: 15 | B20: JUAN MARTIN Y MARIA JESUS | C20: 19 | D20: MARZO | E20: 2013 | F20: FELIPE DE JESUS ZARAGOZA ORTEGA | G20: RICARDO MIRANDA CORONADO | H20: AMANDA ENCINAS DE MIRANDA | I20: SERGIO GARIBAY | J20: OFELIA SOTO DE GARIBAY | K20: PBRO.FELIPE DE JESUS ZARAGOZA ORTEGA | L20: 1 | M20: 8 | N20: 15 | V20: 10 | W20: OCTUBRE
A21: 16 | B21: AUDENCIO Y ALMA PATRICIA | C21: 17 | D21: MAYO | E21: 2013 | F21: FELIPE DE JESUS ZARAGOZA ORTEGA | G21: ESTHER OCHOA RENTERIA | H21: VENANCIO HERMENEGILDO OCHOA YEPIZ | I21: PLUTARCO PADILLA | J21: MA DEL REFUGIO ALCANTAR GIL | K21: PBRO.FELIPE DE JESUS ZARAGOZA ORTEGA | L21: 1 | M21: 8 | N21: 16 | V21: 11 | W21: NOVIEMBRE
A22: 17 | B22: OMAR RENATO Y CLARISSA | C22: 15 | D22: JUNIO | E22: 2013 | F22: FELIPE DE JESUS ZARAGOZA ORTEGA | K22: PBRO.FELIPE DE JESUS ZARAGOZA ORTEGA | L22: 1 | M22: 9 | N22: 17 | V22: 12 | W22: DICIEMBRE
A23: 18 | B23: DAVID Y VILMA GIANNINA | C23: 16 | D23: NOVIEMBRE | E23: 2013 | F23: FELIPE DE JESUS ZARAGOZA ORTEGA | G23: ELIA PINEDA GOMEZ | H23: VIDAL PINEDA GOMEZ | I23: GABRIELA PEÑA DE LAGARDA | J23: GUSTAVO LAGARDA ESQUER | K23: PBRO.FELIPE DE JESUS ZARAGOZA ORTEGA | L23: 1 | M23: 9 | N23: 18 | V23: 13
A24: 19 | B24: JUVENTINO Y ELIZABETH | C24: 21 | D24: DICIEMBRE | E24: 2013 | F24: FELIPE DE JESUS ZARAGOZA ORTEGA | G24: JESUS ALBERTO MORALES BORBON | H24: ALEJANDRA CADILLO CHAVEZ | I24: CAROLINA CADILLO CHAVEZ | J24: OMAR PEÑA PADILLA | K24: PBRO.FELIPE DE JESUS ZARAGOZA ORTEGA | L24: 1 | M24: 10 | N24: 19 | V24: 14
A25: 20 | B25: JOSE FRANCISCO Y MISIS PERLA | C25: 27 | D25: DICIEMBRE | E25: 2013 | F25: FELIPE DE JESUS ZARAGOZA ORTEGA | G25: REBECCA HERRERA | H25: MAURICIO AVILA | I25: MIRNA CAMACHO | J25: GLENDA FELIX SALAZAR | K25: PBRO.FELIPE DE JESUS ZARAGOZA ORTEGA | L25: 1 | M25: 10 | N25: 20 | V25: 15
A26: 21 | B26: ABRAHAM GILBERTO Y ELIZABETH | C26: 28 | D26: JUNIO | E26: 2014 | F26: FELIPE DE JESUS ZARAGOZA ORTEGA | G26: ELOY COLOSIO GAMEZ | H26: TERESA MINERVA GARCIA VIRGEN | I26: SILVIA ELODIA VIDRIO GONZALEZ | J26: MARIA TERESA ROMERO VALDEZ | K26: PBRO.FELIPE DE JESUS ZARAGOZA ORTEGA | L26: 1 | M26: 11 | N26: 21 | V26: 16
A27: 22 | B27: JESUS Y MARIA GUADALUPE | C27: 1 | D27: JULIO | E27: 2014 | F27: FELIPE DE JESUS ZARAGOZA ORTEGA | G27: GUADALUPE AVILA GODOY | H27: AGUSTIN BRAU ROJAS | I27: JOSE LUIS ISLAS PACHECO | J27: ZAYDA ANGULO MONTOYA | K27: PBRO.FELIPE DE JESUS ZARAGOZA ORTEGA | L27: 1 | M27: 11 | N27: 22 | V27: 17
A28: 23 | B28: LUIS ALBERTO Y ALMA AURORA | C28: 1 | D28: AGOSTO | E28: 2014 | F28: FELIPE DE JESUS ZARAGOZA ORTEGA | G28: DELFINA GARCIA BUERAS | H28: MARTIN ADOLFO SALAZAR OVIEDO | I28: JUAN ALFONSO LUJAN VILLEGAS | J28: SILVIA SEDANO FERNANDEZ | K28: PBRO.FELIPE DE JESUS ZARAGOZA ORTEGA | L28: 1 | M28: 12 | N28: 23 | V28: 18
A29: 24 | B29: DAVID ENRIQUE Y ELISA DEL CARMEN | C29: 11 | D29: OCTUBRE | E29: 2014 | F29: FELIPE DE JESUS ZARAGOZA ORTEGA | G29: PROSPERO BARBOZA OCHOA | H29: MARIA ELVIRA ROMO DE BARBOZA | I29: RAMON GOMEZ PUENTE | J29: ISABEL CONS JUAREZ | K29: PBRO.FELIPE DE JESUS ZARAGOZA ORTEGA | L29: 1 | M29: 12 | N29: 24 | V29: 19
A30: 25 | B30: CESAR BLADIMIR Y KARLA SOFIA | C30: 18 | D30: OCTUBRE | E30: 2014 | F30: FELIPE DE JESUS ZARAGOZA ORTEGA | G30: MIRIAM SORAYA CAMPILLO SUGICH | H30: JUAN MANUEL RUIZ VILLARREAL | I30: MANUEL GERARDO CAMIPILLO CORRALES | J30: ANA MIRIAM SUGICH VALENZUELA | K30: PBRO.FELIPE DE JESUS ZARAGOZA ORTEGA | L30: 1 | M30: 13 | N30: 25
A31: 26 | B31: IVAN ALEJANDRO Y CINTHIA GUADALUPE | C31: 12 | D31: DICIEMBRE | E31: 2014 | F31: FELIPE DE JESUS ZARAGOZA ORTEGA | G31: HORACIO VACIO MARTINEZ | H31: BERENICE HERNANDEZ SANCHEZ | I31: FREDDY PALMA CARRILLO | J31: MARTHA PATRICIA HERNANDEZ SANCHEZ | K31: PBRO.FELIPE DE JESUS ZARAGOZA ORTEGA | L31: 1 | M31: 13 | N31: 26
A32: 27 | B32: RUBEN Y ABRIL ALEJANDRA | C32: 3 | D32: ENERO | E32: 2015 | F32: FELIPE DE JESUS ZARAGOZA ORTEGA | G32: JUANA YOLANDA ROMERO HERNANDEZ | H32: JESUS GUTIERREZ VELEZ | I32: ROGELIO QUIJADA GONZALEZ | J32: CATALINA GARCIA VALENZUELA | K32: PBRO.FELIPE DE JESUS ZARAGOZA ORTEGA | L32: 1 | M32: 14 | N32: 27
A33: 28 | B33: SERGIO Y HERMELINDA | C33: 14 | D33: MARZO | E33: 2015 | F33: FELIPE DE JESUS ZARAGOZA ORTEGA | G33: ANDRES SAUL DUATT MUÑOZ | H33: NIRVA LUGO SOTO | I33: RICARDO LUGO SOTO | J33: GUADALUPE VALENCIA DUARTE | K33: PBRO.FELIPE DE JESUS ZARAGOZA ORTEGA | L33: 1 | M33: 14 | N33: 28
A34: 29 | B34: JESUS VALENTIN Y MARIA FERNANDA | C34: 2 | D34: MAYO | E34: 2015 | F34: FELIPE DE JESUS ZARAGOZA ORTEGA | G34: JESUS CORONADO CAREAGA | H34: RAMONA AYALA M. | I34: FRANCISCO SANDOVAL | J34: MARGAROTA CASTRO | K34: PBRO.FELIPE DE JESUS ZARAGOZA ORTEGA | L34: 1 | M34: 15 | N34: 29
A35: 30 | B35: RENE Y OLGA IRENE | C35: 23 | D35: MAYO | E35: 2015 | F35: FELIPE DE JESUS ZARAGOZA ORTEGA | G35: LUIS RICARDO ZAZUETA GUTIERREZ | H35: MARIA ELENA GUARDIAN SOTO | I35: JULIO CESAR ENCINAS LEON | J35: LUCIA GONZALEZ GAMENOS | K35: PBRO.FELIPE DE JESUS ZARAGOZA ORTEGA | L35: 1 | M35: 15 | N35: 30
A36: 31 | B36: MANUEL IGNACIO Y MARIA OLIVIA | C36: 6 | D36: JUNIO | E36: 2015 | F36: FELIPE DE JESUS ZARAGOZA ORTEGA | G36: LUIS ARTURO PADILLA VALDIVIA | H36: MARISOL VILLALOBOS RUIZ | I36: LUCIELA CORONADO SAAVEDRA | J36: MANUEL DE JESUS VELAZQUEZ NIEBLAS | K36: PBRO.FELIPE DE JESUS ZARAGOZA ORTEGA | L36: 1 | M36: 16 | N36: 31
A37: 32 | B37: ALFONSO ERNESTO Y MARIA TERESA | C37: 31 | D37: OCTUBRE | E37: 2015 | F37: FELIPE DE JESUS ZARAGOZA ORTEGA | G37: ALAN PALACIOS | H37: CECILIA JANETH VALENCIA LOPEZ | I37: URIEL ERNESTO LARA VELAZQUEZ | J37: ANA ISABEL VILLEGAS FRANCO | K37: PBRO.FELIPE DE JESUS ZARAGOZA O. | L37: 1 | M37: 16 | N37: 32 | V37: 12 | W37: DICIEMBRE
A38: 33 | B38: ALEXANDER MICHAEL Y MARÍA DE LA LUZ | C38: 7 | D38: NOVIEMBRE | E38: 2015 | F38: FELIPE DE JESUS ZARAGOZA ORTEGA | G38: MA. LAURA SERRANO GENDA | H38: CARLOS RICO GARIBALDI | I38: RAQUEL SERRANO DE MORENO | J38: ROSALIO MORENO DURAZO | K38: PBRO. GERARDO CAMACHO PONCE | L38: 1 | M38: 17 | N38: 33 | V38: 13
A39: 34 | B39: MIGUEL Y GUADALUPE | C39: 28 | D39: NOVIEMBRE | E39: 2015 | F39: FELIPE DE JESUS ZARAGOZA ORTEGA | G39: LUIS SARMIENTO | H39: SILVIA CASTRO SILVAIN | I39: ROSA BOLZ | J39: JESÚS BULMARO PEÑA | K39: PBRO. FELIPE DE JESÚS ZARAGOZA O. | L39: 1 | M39: 17 | N39: 34 | V39: 14
A40: 35 | B40: JORGE Y SELENE GUADALUPE | C40: 20 | D40: FEBRERO | E40: 2016 | F40: FELIPE DE JESUS ZARAGOZA ORTEGA | G40: GENARO CAMPOS BAÑUELOS | H40: CARMINA YAHAIRA DELGADO | I40: SERENA MIRANDA DE LA ROSA | J40: PEDRO ERNESTO SALINAS | K40: PBRO. FELIPE DE JESÚS ZARAGOZA O. | L40: 1 | M40: 18 | N40: 35 | V40: 15
A41: 36 | B41: SERGIO IVAN Y CINTIA NAYELY | C41: 19 | D41: DICIEMBRE | E41: 2015 | F41: FELIPE DE JESUS ZARAGOZA ORTEGA | G41: ELVIA PARADA JIEMENZ | H41: RAFAEL CORDOVA CONS | I41: BEATRIZ ELENA QUINTERO VERDUGO | J41: SANTOS ERNESTO JIMENEZ GARCIA | K41: PBRO. FELIPE DE JESÚS ZARAGOZA O. | L41: 1 | M41: 18 | N41: 36 | V41: 16
A42: 37 | B42: MARIO ALBERTO Y JESSICA LIZETTE | C42: 8 | D42: OCTUBRE | E42: 2016 | F42: FELIPE DE JESUS ZARAGOZA ORTEGA | G42: CÉSAR JESÚS ZÚÑIGA ARECHIGA | H42: ELGA ADERLIN DE LOS RÍOS LÓPEZ | I42: JOSÉ DE JESÚS MONTES RAMOS | J42: MARINA LEPE AGRAZ | K42: PBRO. FELIPE DE JESÚS ZARAGOZA O. | L42: 1 | M42: 19 | N42: 37 | V42: 17
A43: 38 | B43: RUBÉN GUADALUPE Y CLAUDIA | C43: 15 | D43: OCTUBRE | E43: 2016 | F43: FELIPE DE JESUS ZARAGOZA ORTEGA | G43: NATALIHE SAINZ ARAOZ | H43: JOSÉ CARLOS ESQUER NIEBLAS | I43: JESÚS RAMÓN GONZÁLEZ ECHEVERRÍA | J43: FCA. ANGÉLICA GONZÁLEZ ECHEVERRIA | K43: PBRO. FELIPE DE JESÚS ZARAGOZA O. | L43: 1 | M43: 19 | N43: 38 | V43: 18
...

Sheet IMPRESION-MATRIMONIO
A1: 61
C3: =LOOKUP($A$1,MATRIMONIO!$A$7:B1017) -> REY IVAN y SOFIA ARIZBETH
D7: =IF(LOOKUP($A$1,MATRIMONIO!$A$7:C1017)=0," ",LOOKUP($A$1,MATRIMONIO!$A$7:C1017)) -> 22 | F7: =IF(LOOKUP($A$1,MATRIMONIO!$A$7:D1017)=0," ",LOOKUP($A$1,MATRIMONIO!$A$7:D1017)) -> OCTUBRE | I7: =IF(LOOKUP($A$1,MATRIMONIO!$A$7:E1017)=0," ",LOOKUP($A$1,MATRIMONIO!$A$7:E1017)) -> 2022 | L7: =IF(LOOKUP($A$1,MATRIMONIO!$A$7:F1017)=0," ",LOOKUP($A$1,MATRIMONIO!$A$7:F1017)) -> GERARDO CAMACHO PONCE
C9: =IF(LOOKUP($A$1,MATRIMONIO!$A$7:G1017)=0," ",LOOKUP($A$1,MATRIMONIO!$A$7:G1017)) -> MARTÍN VICENTE OLIVAS OLIVAS | K9: =LOOKUP($A$1,MATRIMONIO!$A$7:H1017) -> FRANCISCA REYNOZA GONZÁLEZ
C11: =IF(LOOKUP($A$1,MATRIMONIO!$A$7:I1017)=0," ",LOOKUP($A$1,MATRIMONIO!$A$7:I1017)) -> JOSÉ FRANCISCO MENDOZA GONZÁLEZ | K11: LUZ ALEJANDRA VALENZUELA CÓRDOVA
F13: =LOOKUP($A$1,MATRIMONIO!$A$7:L1017) -> 1 | I13: =LOOKUP($A$1,MATRIMONIO!$A$7:M1017) -> 31
F14: =LOOKUP($A$1,MATRIMONIO!$A$7:N1017) -> 61 | L14: =IF(LOOKUP($A$1,MATRIMONIO!$A$7:K1017)="","",LOOKUP($A$1,MATRIMONIO!$A$7:K1017)) -> PBRO. GERARDO CAMACHO PONCE
C20: NOTA: SOLO TECLEAR EN LA COLUMNA A1 EL NUMERO CORRESPONDA EN LA HOJA MATRIMONIO

Sheet 1ra.COMUNION
C1: CERTIFICADO DE PRIMERA COMUNION 2011
C2: NIÑO(A) | D2: DIA | E2: MES | F2: AÑO | G2: MAMA | H2: PAPA | I2: MADRINA O PADRINO | J2: PÁRROCO
C5: CESAR ROMO BURRUEL | D5: 6 | E5: JUNIO | F5: 2010 | G5: VANIA JANETH BURRUEL MADA | H5: CESAR ROMO CANIZALEZ | I5: EDNA LORENIA BURRUEL MADA Y LUIS ADRIAN BURRUEL MADA | J5: FELIPE DE JESUS ZARAGOZA ORTEGA
C33: CERTIFICADO DE PRIMERA COMUNION 2011
C34: NIÑO(A) | D34: DIA | E34: MES | F34: AÑO | G34: MAMA | H34: PAPA | I34: MADRINA O PADRINO | J34: PÁRROCO
A35: 1 | B35: 1 | C35: JOSE SANTOS LOPEZ RAMIREZ | D35: 9 | E35: JUNIO | F35: 2011 | G35: MA. CONCEPCION RAMIREZ B. | H35: CONRADO LOPEZ SOTO | I35: MARIA VIRGINIA LOPEZ SOTO | R35: 1 | S35: ENERO
R36: 2 | S36: FEBRERO
C37: MICHELLE ALEJANDRA LEON TELLEZ | D37: 11 | E37: JUNIO | F37: 2011 | G37: GUILLERMO LEON ROMERO | H37: AIDA TELLEZ HERNANDEZ | I37: CARLOS ARCE PACHECO Y MAGDALENA ROMO | R37: 3 | S37: MARZO
R38: 4 | S38: ABRIL
R39: 5 | S39: MAYO
A40: 2 | B40: 2 | C40: PAULINA ALEJANDRA MADRID HURTADO | D40: 11 | E40: JUNIO | F40: 2011 | G40: CYNTHIA GUADALUPE HURTADO HERRERA | H40: JOSE LUIS MADRID SALAZAR | I40: CRISTINA GARCES FONTES | R40: 6 | S40: JUNIO
A41: 3 | B41: 3 | C41: VALERIA GUADALUPE LOPEZ CHAVEZ | D41: 4 | E41: JUNIO | F41: 2011 | G41: MA. DEL CARMEN CHAVEZ JUAREZ | H41: JULIO CESAR LOPEZ MADRID | I41: MARIA DEL ROSARIO JUAREZ ANDRADE | R41: 7 | S41: JULIO
A42: 4 | B42: 4 | C42: AIME GONZALEZ BELTRAN | D42: 18 | E42: JUNIO | F42: 2011 | G42: ESTHELA BELTRAN RUELAS | H42: JESUS MARTIN GONZALEZ BRACAMONTES | I42: MONICA GONZALEZ BRACAMONTES | R42: 8 | S42: AGOSTO
A43: 5 | B43: 5 | C43: ALAN FRANCISCO CORDOVA CASTILLO | D43: 18 | E43: JUNIO | F43: 2011 | G43: MONICA CASTILLO MARTINEZ | H43: FRANCISCO JAVIER CORDOVA LOPEZ | I43: HAYDEE CASTILLO MARTINEZ | R43: 9 | S43: SEPTIEMBRE
A44: 6 | B44: 6 | C44: ALESSANDRO OTERO GARCIA | D44: 18 | E44: JUNIO | F44: 2011 | G44: NORMA ANGELICA GARCIA SANCHEZ | H44: CESAR BENJAMIN OTERO LEON | I44: ARTURO DOMINGO LOPEZ REA Y BLANCA ELENA OCHOA SANCHEZ | R44: 10 | S44: OCTUBRE
A45: 7 | B45: 7 | C45: ANA MARIA SALAZAR VALDEZ | D45: 18 | E45: JUNIO | F45: 2011 | G45: ANA BEL VALDEZ MUÑOZ | H45: CESAR ANTONIO SALAZAR LOPEZ | I45: CYNTHIA SELENE ALVAREZ SALAZAR | R45: 11 | S45: NOVIEMBRE
A46: 8 | B46: 8 | C46: ANDREA YAMILETH CARPIO NOGALES | D46: 18 | E46: JUNIO | F46: 2011 | G46: NORMA ALICIA NOGALES CONTRERAS | H46: GERMAN ARMANDO CARPIO SOLIS | I46: LUZ MARGOT NOGALES CONTRERAS | R46: 12 | S46: DICIEMBRE
A47: 9 | B47: 9 | C47: JUAN BENJAMIN GAXIOLA GODINEZ | D47: 18 | E47: JUNIO | F47: 2011 | G47: EMMA YAMEL GODINEZ VALENZUELA | H47: BENJAMIN GAXIOLA LOYA | I47: DORENA GAXIOLA LOYA Y ROBERTO LOPEZ VARGAS | R47: 13
A48: 10 | B48: 10 | C48: BRYAN IVAN CORDOVA FELIX | D48: 18 | E48: JUNIO | F48: 2011 | G48: KARLA DENICE FELIX BARRERAS | H48: IVAN RAFAEL CORDOVA MORENO | I48: PAOLA HURTADO BARRERAS | R48: 14
A49: 11 | B49: 11 | C49: CARLOS ESTEBAN CORTES LABASTIDA | D49: 18 | E49: JUNIO | F49: 2011 | G49: ALMA PATRICIA LABASTIDA CASTILLO | H49: CARLOS ALBERTO CORTES MALDONADO | I49: ERICA MARIA LABASTIDA CASTILLO | R49: 15
A50: 12 | B50: 12 | C50: CHRISTIAN NOE ZENDEJAS ESQUER | D50: 18 | E50: JUNIO | F50: 2011 | G50: KARLA MARIA ESQUER PIRI | H50: ORLANDO ZENDEJAS RANGEL | I50: NORA GPE. ESQUER PIRI Y FCO. RUBEN MORENO GUERRA | R50: 16
A51: 13 | B51: 13 | C51: DANIEL ARMANDO SAMANIEGO MORENO | D51: 18 | E51: JUNIO | F51: 2011 | G51: MARIA FRANCELIA MORENO OCHOA | H51: DANIEL ALBERTO SAMANIEGO QUIJADA | I51: LUIS FERNANDO ROMERO MORENO | R51: 17
A52: 14 | B52: 14 | C52: DANIELA GARCIA TIRADO | D52: 18 | E52: JUNIO | F52: 2011 | G52: GABRIELA TIRADO MEZA | H52: JESUS ARMANDO GARCIA LOPEZ | I52: ISABEL ROLDAN MORALES Y CLAUDIA LUGO GUILLEN | R52: 18
A53: 15 | B53: 15 | C53: DAVID SAAVEDRA MORENO | D53: 18 | E53: JUNIO | F53: 2011 | G53: GLORIA BERENICE MORENO LOPEZ | H53: BALTAZAR SAAVEDRA VALENCIA | I53: IGNACIO MORENO LOPEZ | R53: 19
A54: 16 | B54: 16 | C54: DIEGO ALEJANDRO TORRERO GRACIA | D54: 18 | E54: JUNIO | F54: 2011 | G54: GABRIELA PATRICIA GRACIA PACHECO | H54: JOSE SOLEDAD TORRERO BORBON | I54: ANERIS GPE. MARTINEZ PACHECO Y GABRIEL RODRIGUEZ | R54: 20
A55: 17 | B55: 17 | C55: DYLAN AXEL OVIEDO VALENZUELA | D55: 18 | E55: JUNIO | F55: 2011 | G55: BRISA JEANETH VALENZUELA IZAGUIRRE | H55: CARLOS ALBERTO OVIEDO MORA | I55: GUSTAVO SOTELO SALGADO Y LUCIA ESPERANZA VILLA QUIJADA | R55: 21
A56: 18 | B56: 18 | C56: ELENA ELIZONDO GALINDO | D56: 18 | E56: JUNIO | F56: 2011 | G56: ANA MINERVA GALINDO BRINGAS | H56: GIL ELIZONDO SORIA | I56: MARIA LUISA BRINGAS ESPINOZA | R56: 22
A57: 19 | B57: 19 | C57: ERICK FRANCISCO SOLORZANO MEDINA | D57: 18 | E57: JUNIO | F57: 2011 | G57: MARIA LUCIA MEDINA TONA | H57: FRANCISCO SOLORZANO SANCHEZ | I57: JOSE NOE ROMERO BOJORQUEZ Y THAYDE ANA MENENDEZ GUZMAN | R57: 23
A58: 20 | B58: 20 | C58: ERICKA LIZBETH SALAZAR ROMERO | D58: 18 | E58: JUNIO | F58: 2011 | G58: MARIA TERESA ROMERO VALDEZ | H58: MIRKO ANTONIO SALAZAR ESPINOZA | I58: MARCOS ANTONIO GUTIERREZ | R58: 24
... A65: 27 | B65: 27 | C65: IVAN TADEO ENCINAS GARCIA | D65: 18 | E65: JUNIO | F65: 2011 | G65: LUZ MERCEDES GARCIA RIVERA | H65: VICTOR MANUEL ENCINAS FIGUEROA | I65: ALBERTO MORALES GONZALEZ Y EMMA LUZ DEMONTE ESTUPIÑAN | R65: 31
A66: 28 | B66: 28 | C66: JESUS MARTIN GONZALEZ BELTRAN | D66: 18 | E66: JUNIO | F66: 2011 | G66: ESTHELA BELTRAN RUELAS | H66: JESUS MARTIN GONZALEZ BRACAMONTES | I66: PABLO SANCHEZ VAZQUEZ
A67: 29 | B67: 29 | C67: JESUS AMIN VIDAURRAZAGA MOSRI | D67: 18 | E67: JUNIO | F67: 2011 | G67: ROSA MARIAM MOSRI NIEBLAS | H67: JESUS ARMANDO VIDAURRAZAGA GRACIA | I67: HALIM OCTAVIO MOSRI NIEBLAS Y LIZETH MARIANA VIDAURRAZAGA GRACIA
A68: 30 | B68: 30 | C68: JOANNA GUADALUPE MENDIVIL LOPEZ | D68: 18 | E68: JUNIO | F68: 2011 | G68: VERONICA LOPEZ RUBIO | H68: CARLOS ISRAEL MENDIVIL SOTO | I68: ANA GABRIELA ECHEVERRIA RUBIO
A69: 31 | B69: 31 | C69: JONATHAN HERNANDEZ ANDALON | D69: 18 | E69: JUNIO | F69: 2011 | G69: LILIANA ANDALON MARTINEZ | H69: JOSE RAMIRO HERNANDEZ MARIN | I69: JACQUELINE MORALES MARTINEZ
A70: 32 | B70: 32 | C70: JOSE ANGEL GARCIA ZAZUETA | D70: 18 | E70: JUNIO | F70: 2011 | G70: MIRIAM ZAZUETA PEREZ | H70: FELIPE ANGELES GARCIA NIEBLAS | I70: RUBEN ERNESTO ZAZUETA PEREZ Y ANA MARIA LENDO PEREZ
A71: 33 | B71: 33 | C71: JOSE SEBASTIAN TORRERO GRACIA | D71: 18 | E71: JUNIO | F71: 2011 | G71: GABRIELA PATRICIA GRACIA PACHECO | H71: JOSE SOLEDAD TORRERO BORBON | I71: ANA CELIA MARTINEZ DE GRACIA Y PABLO FRANCISCO GRACIA PACHECO
A72: 34 | B72: 34 | C72: JOSE MANUEL CALVARIO LEON | D72: 18 | E72: JUNIO | F72: 2011 | G72: MARTINA LEON PULIDO | H72: ARMANDO CALVARIO PARRA | I72: DENISSE A. LEON PULIDO
A73: 35 | B73: 35 | C73: JULIETA MENDOZA VILLA | D73: 18 | E73: JUNIO | F73: 2011 | G73: YADIRA ELENA VILLA GIL | H73: RASIEL ANTONIO MENDOZA RUIZ | I73: ZULEMA ALVAREZ ANDRADE Y ELSA MARIA AGUILERA
A74: 36 | B74: 36 | C74: KEVIN DANIEL FIGUEROA DE LA TORRE | D74: 18 | E74: JUNIO | F74: 2011 | G74: MA. DE JESUS DE LA TORRE MACHUCA | H74: MANUEL DE JESUS FIGUEROA ESPINOZA | I74: CLAUDIA KARINA FIGUEROA ESPINOZA
A75: 37 | B75: 37 | C75: LEONARDO MENDOZA ESQUER | D75: 18 | E75: JUNIO | F75: 2011 | G75: ALMA GRISELDA ESQUER CAMPAS | H75: LEONARDO MENDOZA VALENZUELA | I75: LUIS VIDAL MOLINA Y FRANCISCA BELTRAN
...

Sheet IMPRESION-COMUNION
A1: 2715
C6: =LOOKUP($A$1,'1ra.COMUNION'!$B$35:C3016) -> ROBERTO ZAMORA CANTUA
D8: =IF(LOOKUP($A$1,'1ra.COMUNION'!$B$35:D3016)=0," ",LOOKUP($A$1,'1ra.COMUNION'!$B$35:G3018)) -> GILBERTO ZAMORA ORTEGA | I8: =IF(LOOKUP($A$1,'1ra.COMUNION'!$B$35:H3018)=0," ",LOOKUP($A$1,'1ra.COMUNION'!$B$35:H3018)) -> FLOR IVETTE CANTUA MATUS
H9: =LOOKUP(A1,'1ra.COMUNION'!B35:D3306) -> 4 | K9: =LOOKUP(A1,'1ra.COMUNION'!B35:E3306) -> JUNIO | M9: =LOOKUP(A1,'1ra.COMUNION'!B35:F3306) -> 2021
C12: =LOOKUP($A$1,'1ra.COMUNION'!$B$35:I3018) -> ALAN RENE CANTUA MATUS
L14: =IF(LOOKUP($A$1,'1ra.COMUNION'!$B$35:J1044)=""," ",LOOKUP($A$1,'1ra.COMUNION'!$B$35:J1044))
C20: NOTA: SOLO TECLEAR EN LA COLUMAN A1 EL NUMERO CORRESPONDA EN LA HOJA 1ra.COMUNION

Sheet CONFIRMACION
B3: CERTIFICADO DE CONFIRMACION 2010
B4: 4 DE JUNIO 2010
B5: NIÑA O NIÑO | C5: DIA | D5: MES | E5: AÑO | F5: PAPA | G5: MAMA | H5: MADRINA O PADRINO | I5: ARZOBISPO | J5: PARROCO | K5: LIBRO | L5: PAGINA | M5: PARTIDA
A8: 1 | B8: ANA CAROLINA ENRIQUEZ AGUIRRE | C8: 4 | D8: JUNIO | E8: 2010 | F8: GENARO ALBERTO ENRIQUEZ RASCON | G8: ANA CECILIA AGUIRRE MARTINEZ | H8: MAURICIO ENRIQUEZ RASCON | I8: JOSE ULISES MACIAS SALCEDO | J8: FELIPE DE JESUS ZARAGOZA ORTEGA | K8: 1 | L8: 1 | M8: 1
A9: 2 | B9: JUAN ANTONIO RAMIREZ RUIZ | C9: 4 | D9: JUNIO | E9: 2010 | F9: JUAN ANTONIO RAMIREZ PAREDES | G9: LUZ DEL CARMEN RUIZ TERAN | H9: JUAN ANTONIO RAMIREZ PAREDES | I9: JOSE ULISES MACIAS SALCEDO | J9: FELIPE DE JESUS ZARAGOZA ORTEGA | K9: 1 | L9: 1 | M9: 2
A10: 3 | B10: FRANCISCO JAVIER VALENCIA CORRALES | C10: 4 | D10: JUNIO | E10: 2010 | F10: FRANCISCO JAVIER VALENCIA DIAZ | G10: ALICIA CORRALES ROBLES | H10: FRANCISCO JAVIER VALENCIA DIAZ | I10: JOSE ULISES MACIAS SALCEDO | J10: FELIPE DE JESUS ZARAGOZA ORTEGA | K10: 1 | L10: 2 | M10: 3
A11: 4 | B11: LUIS ANGEL BORBON MONTES | C11: 4 | D11: JUNIO | E11: 2010 | F11: MIGUEL ANGEL BORBON CUELLAR | G11: HERMENEGILDA MONTES VALENZUELA | H11: ROSA ISELA MONTES VALENZUELA | I11: JOSE ULISES MACIAS SALCEDO | J11: FELIPE DE JESUS ZARAGOZA ORTEGA | K11: 1 | L11: 2 | M11: 4
A12: 5 | B12: CARLOS DE JESUS BRACAMONTES ESTRADA | C12: 4 | D12: JUNIO | E12: 2010 | F12: JOSE RAMON BRACAMONTES ESTRADA | G12: ERIKA VALENZUELA BELTRAN | H12: FRANCISCO A. RODRIGUEZ A. | I12: JOSE ULISES MACIAS SALCEDO | J12: FELIPE DE JESUS ZARAGOZA ORTEGA | K12: 1 | L12: 3 | M12: 5
A13: 6 | B13: AARON MICHEL ESESARTE RAMOS | C13: 4 | D13: JUNIO | E13: 2010 | F13: WILBER ESESARTE TOLEDO | G13: ELVIA RAMOS COTA | H13: REYES SANCHEZ CARILLO | I13: JOSE ULISES MACIAS SALCEDO | J13: FELIPE DE JESUS ZARAGOZA ORTEGA | K13: 1 | L13: 3 | M13: 6
A14: 7 | B14: LUIS ANGEL MOLINA ARAGON | C14: 4 | D14: JUNIO | E14: 2010 | F14: RAFAEL MOLINA ARCE | G14: CONCEPCION ARAGON MENDIVIL | H14: RAFAELA BARRERAS SAÑUDO | I14: JOSE ULISES MACIAS SALCEDO | J14: FELIPE DE JESUS ZARAGOZA ORTEGA | K14: 1 | L14: 4 | M14: 7
A15: 8 | B15: CARLOS ALEXIS PORTILLO GUZMAN | C15: 4 | D15: JUNIO | E15: 2010 | F15: CARLOS RENE PORTILLO JACOBO | G15: DORA MARIA GUZMAN PEREZ | H15: JORGE RIVERA VAZQUEZ | I15: JOSE ULISES MACIAS SALCEDO | J15: FELIPE DE JESUS ZARAGOZA ORTEGA | K15: 1 | L15: 4 | M15: 8
A16: 9 | B16: ALFREDO RAMIREZ BURGUEÑO | C16: 4 | D16: JUNIO | E16: 2010 | F16: MANUEL DE JESUS RAMIREZ MOROYOQUI | G16: ROSARIO ADRIANA BURGUEÑO | H16: JUAN MIGUEL NORZAGARY FELIX | I16: JOSE ULISES MACIAS SALCEDO | J16: FELIPE DE JESUS ZARAGOZA ORTEGA | K16: 1 | L16: 5 | M16: 9
A17: 10 | B17: CAMILA ALCANTAR EVANS | C17: 4 | D17: JUNIO | E17: 2010 | F17: JUAN MANUEL ALCANTAR CORELLA | G17: MARIA GUADALUPE EVANS DE ALCANTAR | H17: MYRNA DANIELA ESCALANTE EVANS | I17: JOSE ULISES MACIAS SALCEDO | J17: FELIPE DE JESUS ZARAGOZA ORTEGA | K17: 1 | L17: 5 | M17: 10
A18: 11 | B18: HIRLANY DIANEY CHAIDEZ AMAYA | C18: 4 | D18: JUNIO | E18: 2010 | F18: JORGE CHAIDEZ GUZMAN | G18: SILVIA AMAYA CRUZ | H18: MELINA CASTILLO RAMIREZ | I18: JOSE ULISES MACIAS SALCEDO | J18: FELIPE DE JESUS ZARAGOZA ORTEGA | K18: 1 | L18: 6 | M18: 11
A19: 12 | B19: JESUS ANTONIO RAMIREZ LUNA | C19: 4 | D19: JUNIO | E19: 2010 | G19: MARTHA CECILIA RAMIREZ LUNA | H19: JESUS GUSTAVO RODRIGUEZ LUNA | I19: JOSE ULISES MACIAS SALCEDO | J19: FELIPE DE JESUS ZARAGOZA ORTEGA | K19: 1 | L19: 6 | M19: 12
A20: 13 | B20: ELVIA ALICIA GRADILLAS MOJUTA | C20: 4 | D20: JUNIO | E20: 2010 | F20: MARCO ANTONIO GRADILLAS QUINTANA | G20: MARIA ARMIDA MOJUTA GRACIA | H20: MARIA GLORIA MARTINA GRADILLAS QUINTANA | I20: JOSE ULISES MACIAS SALCEDO | J20: FELIPE DE JESUS ZARAGOZA ORTEGA | K20: 1 | L20: 7 | M20: 13
A21: 14 | B21: CLARA ALEXIA GRADILAS MOJUTA | C21: 4 | D21: JUNIO | E21: 2010 | F21: MARCO ANTONIO GRADILLAS QUINTANA | G21: MARIA ARMIDA MOJUTA GRACIA | H21: ESTHER JUDITH GAXIOLA | I21: JOSE ULISES MACIAS SALCEDO | J21: FELIPE DE JESUS ZARAGOZA ORTEGA | K21: 1 | L21: 7 | M21: 14
A22: 15 | B22: EDGAR LEONARDO DE AGUAYO PADILLA | C22: 4 | D22: JUNIO | E22: 2010 | F22: GUSTAVO L. DE AGUAYO A. | G22: BLANCA AZUCENA PADILLA I. | H22: JORGE ALFREDO PADILLA IBARRA | I22: JOSE ULISES MACIAS SALCEDO | J22: FELIPE DE JESUS ZARAGOZA ORTEGA | K22: 1 | L22: 8 | M22: 15
A23: 16 | B23: MARIA JOSE DE AGUAYO PADILLA | C23: 4 | D23: JUNIO | E23: 2010 | F23: GUSTAVO L. DE AGUAYO A. | G23: BLANCA AZUCENA PADILLA I. | H23: LETICIA GUADALUPE AGUAYO ARIAS | I23: JOSE ULISES MACIAS SALCEDO | J23: FELIPE DE JESUS ZARAGOZA ORTEGA | K23: 1 | L23: 8 | M23: 16
A24: 17 | B24: SEBASTIAN SALAS MARES | C24: 4 | D24: JUNIO | E24: 2010 | F24: MARIO EDUARDO SALAS HERNANDEZ | G24: MARIANA MARES TORRES | H24: AGUSTIN SALAS HERNANDEZ | I24: JOSE ULISES MACIAS SALCEDO | J24: FELIPE DE JESUS ZARAGOZA ORTEGA | K24: 1 | L24: 9 | M24: 17
A25: 18 | B25: PATRICIA GUADALUPE ANDRADE DURAZO | C25: 4 | D25: JUNIO | E25: 2010 | F25: ISRAEL ANDRADE MAGAÑA | G25: CLAUDIA DURAZO MUNGUIA | H25: MARIA DOLORES DURAZO | I25: JOSE ULISES MACIAS SALCEDO | J25: FELIPE DE JESUS ZARAGOZA ORTEGA | K25: 1 | L25: 9 | M25: 18
A26: 19 | B26: JESUS GUILLERMO RAMOS OLEA | C26: 4 | D26: JUNIO | E26: 2010 | F26: FRANCISCO JAVIER RAMOS AHUMADA | G26: SONIA ELIZABETH OLEA FIGUEROA | H26: JESUS GUSTAVO RODRIGUEZ LUNA | I26: JOSE ULISES MACIAS SALCEDO | J26: FELIPE DE JESUS ZARAGOZA ORTEGA | K26: 1 | L26: 10 | M26: 19
A27: 20 | B27: ANGEL ALEXIS SOLIS PAYAN | C27: 4 | D27: JUNIO | E27: 2010 | F27: JOSE A. SOLIS | G27: CRUZ PAYAN | H27: FIDEL PAYAN OLVERA | I27: JOSE ULISES MACIAS SALCEDO | J27: FELIPE DE JESUS ZARAGOZA ORTEGA | K27: 1 | L27: 10 | M27: 20
A28: 21 | B28: DANIEL GILBERTO ESCARCEGA MAYORQUIN | C28: 4 | D28: JUNIO | E28: 2010 | F28: JUAN CARLOS ESCARCEGA MADRID | G28: EVA LIDIA MAYORQUIN | H28: JORGE FRANCISCO RUIZ MADRID | I28: JOSE ULISES MACIAS SALCEDO | J28: FELIPE DE JESUS ZARAGOZA ORTEGA | K28: 1 | L28: 11 | M28: 21
A29: 22 | B29: JULIO CESAR MIRANDA NAVARRO | C29: 4 | D29: JUNIO | E29: 2010 | F29: MARCO VINICIO MIRANDA | G29: SILVIA GUADALUPE NAVARRO | H29: JESUS ALBERTO FLORES BALDERRAMA | I29: JOSE ULISES MACIAS SALCEDO | J29: FELIPE DE JESUS ZARAGOZA ORTEGA | K29: 1 | L29: 11 | M29: 22
A30: 23 | B30: MARTHA TERESITA LEON RAMOS | C30: 4 | D30: JUNIO | E30: 2010 | F30: GUILLERMO LEON RODRIGUEZ | G30: NILLIRMA YSELA RAMOS GARCIA | H30: ELVIRA CABUTO | I30: JOSE ULISES MACIAS SALCEDO | J30: FELIPE DE JESUS ZARAGOZA ORTEGA | K30: 1 | L30: 12 | M30: 23
A31: 24 | B31: MARIA GUADALUPE CORONADO MEJIA | C31: 4 | D31: JUNIO | E31: 2010 | F31: EDUARDO RAMON CORONADO CONTRERAS | G31: MARIA DEL CARMEN MEJIA DOMINGUEZ | H31: MA. GUADALUPE CORONADO CONTREREAS | I31: JOSE ULISES MACIAS SALCEDO | J31: FELIPE DE JESUS ZARAGOZA ORTEGA | K31: 1 | L31: 12 | M31: 24
... A33: 26 | B33: AMERICA JUDITH OLIVAS GARCIA | C33: 4 | D33: JUNIO | E33: 2010 | F33: JESUS MANUEL OLIVAS RIOS | G33: BLANCA ARACELY GARCIA ROMERO | H33: ALMA ANGELICA SAU SESMA | I33: JOSE ULISES MACIAS SALCEDO | J33: FELIPE DE JESUS ZARAGOZA ORTEGA | K33: 1 | L33: 13 | M33: 26
A34: 27 | B34: FRANCISCO GUSTAVO BERNAL | C34: 4 | D34: JUNIO | E34: 2010 | G34: MARIA DEL ROSARIO BERNAL SOTO | H34: CARLOS BERNAL SOTO | I34: JOSE ULISES MACIAS SALCEDO | J34: FELIPE DE JESUS ZARAGOZA ORTEGA | K34: 1 | L34: 14 | M34: 27
A35: 28 | B35: ANTHONY ALEXIS SANCHEZ HERNANDEZ | C35: 4 | D35: JUNIO | E35: 2010 | F35: ANDRES SANCHEZ MEDINA | G35: YELENIA M. HERNANDEZ | H35: RICARDO HERNANDEZ MIRANDA | I35: JOSE ULISES MACIAS SALCEDO | J35: FELIPE DE JESUS ZARAGOZA ORTEGA | K35: 1 | L35: 14 | M35: 28
A36: 29 | B36: BLANCA MAGDALENA CARRILLO GUTIERREZ | C36: 4 | D36: JUNIO | E36: 2010 | F36: DOMINGO ISRAEL CARRILLO GUTIERREZ | G36: BLANCA IRENE GUTIERREZ GRIJALVA | H36: ESTHER ALICIA GOMEZ RODRIGUEZ | I36: JOSE ULISES MACIAS SALCEDO | J36: FELIPE DE JESUS ZARAGOZA ORTEGA | K36: 1 | L36: 15 | M36: 29
A37: 30 | B37: ANGELICA IRAIS LOPEZ HERNANDEZ | C37: 4 | D37: JUNIO | E37: 2010 | F37: JORGE RICARDO LOPEZ ORTEGA | G37: FERNANDA IRAIS HERNANDEZ ZAMORA | H37: FCA. MARTHA YESENIA RUELAS CANO | I37: JOSE ULISES MACIAS SALCEDO | J37: FELIPE DE JESUS ZARAGOZA ORTEGA | K37: 1 | L37: 15 | M37: 30
A38: 31 | B38: CINTHIA EBELICE SANTOYO ROMO | C38: 4 | D38: JUNIO | E38: 2010 | F38: JOAQUIN MARTIN SANTOYO RAMIREZ | G38: IMELDA ALICIA ROMO LACARRA | H38: ANA CECILIA SANTOYO | I38: JOSE ULISES MACIAS SALCEDO | J38: FELIPE DE JESUS ZARAGOZA ORTEGA | K38: 1 | L38: 16 | M38: 31
A39: 32 | B39: ALEXIA FERNANDA VALDEZ MOLINA | C39: 4 | D39: JUNIO | E39: 2010 | F39: JOAQUIN MARTIN SANTOYO RAMIREZ | G39: IMELDA ALICIA ROMO LACARRA | H39: CARMEN CECILIA CASTILLO DURAN | I39: JOSE ULISES MACIAS SALCEDO | J39: FELIPE DE JESUS ZARAGOZA ORTEGA | K39: 1 | L39: 16 | M39: 32
A40: 33 | B40: ANA CLAUDINA VALENZUELA ROMERO | C40: 4 | D40: JUNIO | E40: 2010 | F40: ROBERTO VALENZUELA TREJO | G40: MARITZA ANGELICA ROMERO CORDOVA | H40: MA. DE LOS ANGELES CORDOVA | I40: JOSE ULISES MACIAS SALCEDO | J40: FELIPE DE JESUS ZARAGOZA ORTEGA | K40: 1 | L40: 17 | M40: 33
A41: 34 | B41: ANDREA CAROLINA MENDIVIL LOPEZ | C41: 4 | D41: JUNIO | E41: 2010 | F41: TRINIDAD MENDIVIL VALENZUELA | G41: LUZ AMALIA LOPEZ RODRIGUEZ | H41: GUADALUPE LOPEZ RODRIGUEZ | I41: JOSE ULISES MACIAS SALCEDO | J41: FELIPE DE JESUS ZARAGOZA ORTEGA | K41: 1 | L41: 17 | M41: 34
A42: 35 | B42: ANEL SHIOMARA ARIAS | C42: 4 | D42: JUNIO | E42: 2010 | G42: CLAUDIA ANEL ARIAS CASTRO | H42: MARIA GUADALUPE ARIAS CASTRO | I42: JOSE ULISES MACIAS SALCEDO | J42: FELIPE DE JESUS ZARAGOZA ORTEGA | K42: 1 | L42: 18 | M42: 35
A43: 36 | B43: ANETTE JOSELINE GARCIA OLIVARRIA | C43: 4 | D43: JUNIO | E43: 2010 | F43: JOSE IGNACIO GARCIA FELIX | G43: ALBA ELENA OLIVARRIA LARA | H43: MA. TERESA VEGA | I43: JOSE ULISES MACIAS SALCEDO | J43: FELIPE DE JESUS ZARAGOZA ORTEGA | K43: 1 | L43: 18 | M43: 36
A44: 37 | B44: ANGELA JOSELIN VALENZUELA | C44: 4 | D44: JUNIO | E44: 2010 | G44: ANABEL VALENZUELA NUÑEZ | H44: GISELA GUADALUPE DURAZO MIRANDA | I44: JOSE ULISES MACIAS SALCEDO | J44: FELIPE DE JESUS ZARAGOZA ORTEGA | K44: 1 | L44: 19 | M44: 37
A45: 38 | B45: BRIANDA GUADALUPE CRUZ MONGE | C45: 4 | D45: JUNIO | E45: 2010 | F45: HERIBERTO CRUZ FEDERICO | G45: CECILIA GUADALUPE MONGE | H45: MARIA ISABEL FEDERICO REINA | I45: JOSE ULISES MACIAS SALCEDO | J45: FELIPE DE JESUS ZARAGOZA ORTEGA | K45: 1 | L45: 19 | M45: 38
...

Sheet IMPRESION-CONFIRMACION
A1: 1226
D5: =LOOKUP($A$1,CONFIRMACION!$A$7:B2143) -> VALERIA GUADALUPE MANZANARES INZUNZA
E8: =IF(LOOKUP($A$1,CONFIRMACION!$A$7:F2143)=0," ",LOOKUP($A$1,CONFIRMACION!$A$7:F2143)) -> OMAR MANZANARES DURAZO | I8: =LOOKUP($A$1,CONFIRMACION!$A$7:G2143) -> ADRIANA INZUNZA CALDERON
C12: DON JOSÉ ULISES MACIAS SALCEDO | H12: =IF(LOOKUP($A$1,CONFIRMACION!$A$7:C2147)=0," ",LOOKUP($A$1,CONFIRMACION!$A$7:C2147)) -> 17 | I12: =IF(LOOKUP($A$1,CONFIRMACION!$A$7:D2147)=0," ",LOOKUP($A$1,CONFIRMACION!$A$7:D2147)) -> JUNIO | J12: =IF(LOOKUP($A$1,CONFIRMACION!$A$7:E2147)=0," ",LOOKUP($A$1,CONFIRMACION!$A$7:E2147)) -> 2022
F14: =LOOKUP($A$1,CONFIRMACION!$A$7:H2143) -> MYRIAM GRACIELA DUARTE ARIAS
F15: 2
F16: 53 | I16: =IF(LOOKUP($A$1,CONFIRMACION!A$7:$J2163)=0," ",LOOKUP($A$1,CONFIRMACION!A$7:$J2163)) -> GERARDO CAMACHO PONCE
F17: 106

Sheet CONSTANCIA.BAUTISMO
B3: CONSTANCIA DE BAUTISMO
D5: FECHA NACIMIENTO | G5: LUGAR | J5: FECHA BAUTISMO
B6: NIÑA O NIÑO | D6: DIA | E6: MES | F6: AÑO | G6: DE NACIMIENTO | H6: PAPA | I6: MAMA | J6: DIA | K6: MES | L6: AÑO | M6: MINISTRO | N6: PADRINO | O6: MADRINA | P6: PÁRROCO | Q6: REGISTRO NO. | U6: Libro | V6: Pagina | W6: Acta
A7: 1 | B7: DIEGO RAMIREZ SALADO | D7: 18 | E7: NOVIEMBRE | F7: 2008 | G7: HERMOSILLO SONORA | H7: LUIS FERNANDO RAMIREZ SALCIDO | I7: LILIAN IVETTHE SALADO RODRIGUEZ | J7: 13 | K7: SEPTIEMBRE | L7: 2009 | M7: PBRO. FELIPE DE JESUS ZARAGOZA ORTEGA | N7: SAUL JUSTO MORALES | O7: REYNA OCHOA LANDIN | P7: PBRO. FELIPE DE JESUS ZARAGOZA ORTEGA | Q7: 631 | R7: =H7&" Y "&I7 -> LUIS FERNANDO RAMIREZ SALCIDO Y LILIAN IVETTHE SALADO RODRIGUEZ | S7: =D7&" "&E7&" DE "&F7 -> 18 NOVIEMBRE DE 2008 | T7: =J7&" "&K7&" DE "&L7 -> 13 SEPTIEMBRE DE 2009 | U7: 1 | V7: 1 | W7: 1
A8: 2 | B8: JUAN PABLO ZUÑIGA HUGUEZ | D8: 22 | E8: SEPTIEMBRE | F8: 2009 | G8: HERMOSILLO SONORA | H8: JUAN CARLOS ZUÑIGA QUIROGA | I8: ADRIANA MARGARITA HUGUEZ BARCELO | J8: 14 | K8: NOVIEMBRE | L8: 2009 | M8: PBRO. FELIPE DE JESUS ZARAGOZA ORTEGA | N8: JORGE LOPEZ BARRON Y FLOR DE ESMIRA CAMACHO RABAGO | O8: MARCO ANTONIO ZUÑIGA QUIROGA Y FRANCISCO ADOLFO HUGUEZ BARCELO | P8: PBRO. FELIPE DE JESUS ZARAGOZA ORTEGA | Q8: 1439 | R8: =H8&" Y "&I8 -> JUAN CARLOS ZUÑIGA QUIROGA Y ADRIANA MARGARITA HUGUEZ BARCELO | S8: =D8&" "&E8&" DE "&F8 -> 22 SEPTIEMBRE DE 2009 | T8: =J8&" "&K8&" DE "&L8 -> 14 NOVIEMBRE DE 2009 | U8: 1 | V8: 1 | W8: 2
A9: 3 | B9: JESUS ALFREDO GUTIERREZ AZUCENA | D9: 9 | E9: SEPTIEMBRE | F9: 2008 | G9: HERMOSILLO SONORA | H9: MANUEL ARMANDO GUTIERREZ AMAYA | I9: ANA DOLORES AZUCENA AMPARAMO | J9: 15 | K9: NOVIEMBRE | L9: 2009 | M9: PBRO. FELIPE DE JESUS ZARAGOZA ORTEGA | N9: ARMANDO IBARRA CORONADO | O9: NORA AHIMEE AGUILAR AMAYA | P9: PBRO. FELIPE DE JESUS ZARAGOZA ORTEGA | Q9: 3579 | R9: =H9&" Y "&I9 -> MANUEL ARMANDO GUTIERREZ AMAYA Y ANA DOLORES AZUCENA AMPARAMO | S9: =D9&" "&E9&" DE "&F9 -> 9 SEPTIEMBRE DE 2008 | T9: =J9&" "&K9&" DE "&L9 -> 15 NOVIEMBRE DE 2009 | U9: 1 | V9: 2 | W9: 3
A10: 4 | B10: JESUS ALEJANDRO CLARCK GUTIERREZ | D10: 29 | E10: MAYO | F10: 2009 | G10: HERMOSILLO SONORA | H10: VIDAL CLARK MIRANDA | I10: JOVANA DE JESUS GUTIERREZ LIZO | J10: 15 | K10: NOVIEMBRE | L10: 2009 | M10: PBRO. FELIPE DE JESUS ZARAGOZA ORTEGA | N10: EPIGMENIO CLARK MIRANDA | O10: JOSEFINA LISO GONZALEZ | P10: PBRO. FELIPE DE JESUS ZARAGOZA ORTEGA | Q10: 3007 | R10: =H10&" Y "&I10 -> VIDAL CLARK MIRANDA Y JOVANA DE JESUS GUTIERREZ LIZO | S10: =D10&" "&E10&" DE "&F10 -> 29 MAYO DE 2009 | T10: =J10&" "&K10&" DE "&L10 -> 15 NOVIEMBRE DE 2009 | U10: 1 | V10: 2 | W10: 4
A11: 5 | B11: JESUS CARLOS SOBERANES SALAZAR | D11: 26 | E11: AGOSTO | F11: 1994 | G11: HERMOSILLO SONORA | H11: PORFIRIO SOBERANES OCHOA | I11: AMPARO SALAZAR IBARRA | J11: 21 | K11: NOVIEMBRE | L11: 2009 | M11: PBRO. FELIPE DE JESUS ZARAGOZA ORTEGA | N11: JESUS MARIA SOBERANES OCHOA | O11: RAMONA DURAN GONZALEZ | P11: PBRO. FELIPE DE JESUS ZARAGOZA ORTEGA | Q11: 3607 | R11: =H11&" Y "&I11 -> PORFIRIO SOBERANES OCHOA Y AMPARO SALAZAR IBARRA | S11: =D11&" "&E11&" DE "&F11 -> 26 AGOSTO DE 1994 | T11: =J11&" "&K11&" DE "&L11 -> 21 NOVIEMBRE DE 2009 | U11: 1 | V11: 3 | W11: 5
A12: 6 | B12: RAMON CASTILLO ALVARADO | D12: 15 | E12: FEBRERO | F12: 2009 | G12: HERMOSILLO SONORA | H12: RAMON CASTILLO GAMEZ | I12: MARIA DEL CARMEN ALVARADO VELAZQUEZ | J12: 15 | K12: FEBRERO | L12: 2009 | M12: PBRO. FELIPE DE JESUS ZARAGOZA ORTEGA | N12: MANUEL ANGEL CASTILLO DUARTE | O12: ANA LILIA ALVARADO VELAZQUEZ Y MARIA JESUS GAMEZ OCHOA | P12: PBRO. FELIPE DE JESUS ZARAGOZA ORTEGA | Q12: 1044 | R12: =H12&" Y "&I12 -> RAMON CASTILLO GAMEZ Y MARIA DEL CARMEN ALVARADO VELAZQUEZ | S12: =D12&" "&E12&" DE "&F12 -> 15 FEBRERO DE 2009 | T12: =J12&" "&K12&" DE "&L12 -> 15 FEBRERO DE 2009 | U12: 1 | V12: 3 | W12: 6
A13: 7 | B13: JONAS LOPEZ RAMIREZ | D13: 11 | E13: JULIO | F13: 2009 | G13: HERMOSILLO SONORA | H13: FIDEL GUILLERMO LOPEZ GOMEZ | I13: ANA GUADALUPE RAMIREZ TANORI | J13: 29 | K13: NOVIEMBRE | L13: 2009 | M13: PBRO. FELIPE DE JESUS ZARAGOZA ORTEGA | N13: IVAN GERARDO MILLAN ARVAYO | O13: MARTHA RENEE LOYA CARRANZA | P13: PBRO. FELIPE DE JESUS ZARAGOZA ORTEGA | Q13: 1223 | R13: =H13&" Y "&I13 -> FIDEL GUILLERMO LOPEZ GOMEZ Y ANA GUADALUPE RAMIREZ TANORI | S13: =D13&" "&E13&" DE "&F13 -> 11 JULIO DE 2009 | T13: =J13&" "&K13&" DE "&L13 -> 29 NOVIEMBRE DE 2009 | U13: 1 | V13: 4 | W13: 7
A14: 8 | B14: YARELI STHEFANIA SOLIS NAVARRO | D14: 30 | E14: SEPTIEMBRE | F14: 2008 | G14: HERMOSILLO SONORA | H14: JAVIER SOLIS GUERRERO | I14: NORMA ALICIA NAVARRO TARAZON | J14: 29 | K14: NOVIEMBRE | L14: 2009 | M14: PBRO. FELIPE DE JESUS ZARAGOZA ORTEGA | N14: SAUL HIRAM HERRERA TERAN | O14: DIVA ZULEMA VAZQUEZ DANIEL | P14: PBRO. FELIPE DE JESUS ZARAGOZA ORTEGA | Q14: 4226 | R14: =H14&" Y "&I14 -> JAVIER SOLIS GUERRERO Y NORMA ALICIA NAVARRO TARAZON | S14: =D14&" "&E14&" DE "&F14 -> 30 SEPTIEMBRE DE 2008 | T14: =J14&" "&K14&" DE "&L14 -> 29 NOVIEMBRE DE 2009 | U14: 1 | V14: 4 | W14: 8
A15: 9 | B15: EMI CRISTINA AVILA HERRERA | D15: 27 | E15: SEPTIEMBRE | F15: 2009 | G15: HERMOSILLO SONORA | H15: EDGAR MAURICIO AVILA ALMARAZ | I15: AMELIA REBECA HERRERA VALENZUELA | J15: 12 | K15: DICIEMBRE | L15: 2009 | M15: PBRO. FELIPE DE JESUS ZARAGOZA ORTEGA | N15: MANUEL GERMAN BOSSE BALDERRAMA | O15: MARGARITA CASTRO FELIZ | P15: PBRO. FELIPE DE JESUS ZARAGOZA ORTEGA | R15: =H15&" Y "&I15 -> EDGAR MAURICIO AVILA ALMARAZ Y AMELIA REBECA HERRERA VALENZUELA | S15: =D15&" "&E15&" DE "&F15 -> 27 SEPTIEMBRE DE 2009 | T15: =J15&" "&K15&" DE "&L15 -> 12 DICIEMBRE DE 2009 | U15: 1 | V15: 5 | W15: 9
A16: 10 | B16: FATIMA PAULINA ESCALANTE FIMBRES | D16: 11 | E16: FEBRERO | F16: 2009 | G16: HERMOSILLO SONORA | H16: GERMAN ARTURO ESCALANTE LOPEZ | I16: SUGHEY GUADALUPE FIMBRES DUSTAN | J16: 20 | K16: DICIEMBRE | L16: 2009 | M16: PBRO. FELIPE DE JESUS ZARAGOZA ORTEGA | N16: ARMANDO FIMBRES DUSTAN | O16: FRANCISCA GUTIERREZ AVILA | P16: PBRO. FELIPE DE JESUS ZARAGOZA ORTEGA | Q16: 288 | R16: =H16&" Y "&I16 -> GERMAN ARTURO ESCALANTE LOPEZ Y SUGHEY GUADALUPE FIMBRES DUSTAN | S16: =D16&" "&E16&" DE "&F16 -> 11 FEBRERO DE 2009 | T16: =J16&" "&K16&" DE "&L16 -> 20 DICIEMBRE DE 2009 | U16: 1 | V16: 5 | W16: 10
A17: 11 | B17: EYMMI AYELEN RETES MEZA | D17: 25 | E17: MARZO | F17: 2009 | G17: HERMOSILLO SONORA | I17: LAURA PATRICIA RETES MEZA | J17: 20 | K17: DICIEMBRE | L17: 2009 | M17: PBRO. FELIPE DE JESUS ZARAGOZA ORTEGA | N17: JOSE FRANCISCO RETES MEZA Y LINDA IRASEMA TRILLAS ARVALLO | O17: JOSUE NORBERTO RETES MEZA Y CINTHYA ARACELY ACOSTA MILLAN | P17: PBRO. FELIPE DE JESUS ZARAGOZA ORTEGA | Q17: 617 | R17: =H17&" Y "&I17 -> Y LAURA PATRICIA RETES MEZA | S17: =D17&" "&E17&" DE "&F17 -> 25 MARZO DE 2009 | T17: =J17&" "&K17&" DE "&L17 -> 20 DICIEMBRE DE 2009 | U17: 1 | V17: 6 | W17: 11
A18: 12 | B18: OLIVER HUMBERTO RAMOS MORALES | D18: 21 | E18: MAYO | F18: 2009 | G18: HERMOSILLO SONORA | H18: JOSE HUMBERTO RAMOS BARRERAS | I18: BARBARA MORALES SALCIDO | J18: 24 | K18: DICIEMBRE | L18: 2009 | M18: PBRO. FELIPE DE JESUS ZARAGOZA ORTEGA | N18: FERNANDO BARRERAS AMAVIZCA | O18: MARTHA LETICIA RAMOS BARRRERAS | P18: PBRO. FELIPE DE JESUS ZARAGOZA ORTEGA | Q18: 1897 | R18: =H18&" Y "&I18 -> JOSE HUMBERTO RAMOS BARRERAS Y BARBARA MORALES SALCIDO | S18: =D18&" "&E18&" DE "&F18 -> 21 MAYO DE 2009 | T18: =J18&" "&K18&" DE "&L18 -> 24 DICIEMBRE DE 2009 | U18: 1 | V18: 6 | W18: 12
D20: FECHA NACIMIENTO | G20: LUGAR | J20: FECHA BAUTISMO
B21: NIÑA O NIÑO | D21: DIA | E21: MES | F21: AÑO | G21: DE NACIMIENTO | H21: PAPA | I21: MAMA | J21: DIA | K21: MES | L21: AÑO | M21: MINISTRO | N21: PADRINO | O21: MADRINA | P21: PÁRROCO | Q21: REGISTRO NO. | U21: Libro | V21: Pagina | W21: Acta
A22: 13 | B22: MIGUEL ANGEL CECEÑA LOPEZ | D22: 19 | E22: DICIEMBRE | F22: 2008 | G22: HERMOSILLO, SONORA | I22: VELMA NEREYDA CECEÑA LOPEZ | J22: 16 | K22: ENERO | L22: 2010 | M22: PBRO. FELIPE DE JESUS ZARAGOZA ORTEGA | N22: ENOC BLADIMIR CECEÑA LOPEZ | O22: VERONICA ENCINAS VALENZUELA | P22: PBRO. FELIPE DE JESUS ZARAGOZA ORTEGA | Q22: 174 | R22: =H22&" Y "&I22 -> Y VELMA NEREYDA CECEÑA LOPEZ | S22: =D22&" "&E22&" DE "&F22 -> 19 DICIEMBRE DE 2008 | T22: =J22&" "&K22&" DE "&L22 -> 16 ENERO DE 2010 | U22: 1 | V22: 7 | W22: 13
A23: 14 | B23: LUIS ARMANDO TRUJILLO SIERRA | D23: 6 | E23: DICIEMBRE | F23: 2009 | G23: HERMOSILLO, SONORA | H23: MIGUEL TRUJILLO ZAMORA | I23: GLORIA ALICIA SIERRA ALVAREZ | J23: 14 | K23: FEBRERO | L23: 2010 | M23: PBRO. FELIPE DE JESUS ZARAGOZA ORTEGA | N23: JESUS AUSENCIO SIERRA ALVAREZ | O23: ANA CECILIA TRUJILLO ZAMORA | P23: PBRO. FELIPE DE JESUS ZARAGOZA ORTEGA | Q23: 4987 | R23: =H23&" Y "&I23 -> MIGUEL TRUJILLO ZAMORA Y GLORIA ALICIA SIERRA ALVAREZ | S23: =D23&" "&E23&" DE "&F23 -> 6 DICIEMBRE DE 2009 | T23: =J23&" "&K23&" DE "&L23 -> 14 FEBRERO DE 2010 | U23: 1 | V23: 7 | W23: 14
A24: 15 | B24: ANA CRISTINA VAZQUEZ TIRADO | D24: 2 | E24: DICIEMBRE | F24: 2008 | G24: HERMOSILLO, SONORA | H24: JESUS FLORENCIO VAZQUEZ CARBAJAL | I24: MARIA CRISTINA TIRADO RUIZ | J24: 21 | K24: FEBRERO | L24: 2010 | M24: PBRO. FELIPE DE JESUS ZARAGOZA ORTEGA | N24: CARLOS ENRIQUE TIRADO RUIZ | O24: MARIA DOLORES VEGA APODACA | P24: PBRO. FELIPE DE JESUS ZARAGOZA ORTEGA | Q24: 4750 | R24: =H24&" Y "&I24 -> JESUS FLORENCIO VAZQUEZ CARBAJAL Y MARIA CRISTINA TIRADO RUIZ | S24: =D24&" "&E24&" DE "&F24 -> 2 DICIEMBRE DE 2008 | T24: =J24&" "&K24&" DE "&L24 -> 21 FEBRERO DE 2010 | U24: 1 | V24: 8 | W24: 15
A25: 16 | B25: JESUS ALBERTO GARCIA ROBLES | D25: 24 | E25: JUNIO | F25: 2009 | G25: HERMOSILLO, SONORA | H25: ORLANDO GARCIA ARROYO | I25: SANDRA ALICIA ROBLES ESQUER | J25: 21 | K25: FEBRERO | L25: 2010 | M25: PBRO. FELIPE DE JESUS ZARAGOZA ORTEGA | N25: JUAN FRANCISCO BARRERA SANZUR | O25: ANA MARIA ROBLES ESQUER | P25: PBRO. FELIPE DE JESUS ZARAGOZA ORTEGA | Q25: 486 | R25: =H25&" Y "&I25 -> ORLANDO GARCIA ARROYO Y SANDRA ALICIA ROBLES ESQUER | S25: =D25&" "&E25&" DE "&F25 -> 24 JUNIO DE 2009 | T25: =J25&" "&K25&" DE "&L25 -> 21 FEBRERO DE 2010 | U25: 1 | V25: 8 | W25: 16
A26: 17 | B26: MARTHA DANIELA SUSUKI MONTIEL | D26: 15 | E26: FEBRERO | F26: 2009 | G26: HERMOSILLO, SONORA | H26: MIGUEL ALÑEJO SUSUKI LUGO | I26: MARTHA ZANELLY MONTIEL DIARTE | J26: 21 | K26: FEBRERO | L26: 2010 | M26: PBRO. FELIPE DE JESUS ZARAGOZA ORTEGA | N26: ERIC ARTURO SMITH RAMIREZ | O26: GABRIELA RIVERA DIARTE | P26: PBRO. FELIPE DE JESUS ZARAGOZA ORTEGA | Q26: 981 | R26: =H26&" Y "&I26 -> MIGUEL ALÑEJO SUSUKI LUGO Y MARTHA ZANELLY MONTIEL DIARTE | S26: =D26&" "&E26&" DE "&F26 -> 15 FEBRERO DE 2009 | T26: =J26&" "&K26&" DE "&L26 -> 21 FEBRERO DE 2010 | U26: 1 | V26: 9 | W26: 17
A27: 18 | B27: LIAM EMILIANO GUTIERREZ MENDOZA | D27: 20 | E27: ENERO | F27: 2007 | G27: HERMOSILLO, SONORA | H27: JAVIER ALONSO GUTIERREZ VAZQUEZ | I27: BIANKA RENATA MENDOZA CASTRO | J27: 28 | K27: FEBRERO | L27: 2010 | M27: PBRO. FELIPE DE JESUS ZARAGOZA ORTEGA | N27: JUDAS TADEO MENDEZ VAZQUEZ Y MARIJA DE LOS ANGELES CASTRO RUIZ | O27: OSCAR FIGUEROA M. Y LOURDES LORENA ALCANTAR TAPIA | P27: PBRO. FELIPE DE JESUS ZARAGOZA ORTEGA | Q27: 706 | R27: =H27&" Y "&I27 -> JAVIER ALONSO GUTIERREZ VAZQUEZ Y BIANKA RENATA MENDOZA CASTRO | S27: =D27&" "&E27&" DE "&F27 -> 20 ENERO DE 2007 | T27: =J27&" "&K27&" DE "&L27 -> 28 FEBRERO DE 2010 | U27: 1 | V27: 9 | W27: 18
A28: 19 | B28: AZUL ALEJANDRA LOPEZ FLORES | D28: 5 | E28: JULIO | F28: 2009 | G28: HERMOSILLO, SONORA | H28: ENRIQUE LOPEZ VILLEGAS | I28: MYRIAM ALEJANDRA FLORES VERDUZCO | J28: 7 | K28: MARZO | L28: 2010 | M28: PBRO. FELIPE DE JESUS ZARAGOZA ORTEGA | O28: DANIELA GUADALUPE BAÑUELOS RODRIGUEZ | P28: PBRO. FELIPE DE JESUS ZARAGOZA ORTEGA | Q28: 2994 | R28: =H28&" Y "&I28 -> ENRIQUE LOPEZ VILLEGAS Y MYRIAM ALEJANDRA FLORES VERDUZCO | S28: =D28&" "&E28&" DE "&F28 -> 5 JULIO DE 2009 | T28: =J28&" "&K28&" DE "&L28 -> 7 MARZO DE 2010 | U28: 1 | V28: 10 | W28: 19
A29: 20 | B29: MIRIAM ESTHER GONZALEZ ALVAREZ | D29: 2 | E29: ABRIL | F29: 2001 | G29: HERMOSILLO, SONORA | H29: ISMAEL GONZALEZ FIGUEROA | I29: TERESITA DE JESUS ALVAREZ PEREZ | J29: 3 | K29: ABRIL | L29: 2010 | M29: PBRO. FELIPE DE JESUS ZARAGOZA ORTEGA | N29: JOSE BENITO FRANCO SORIANO | O29: MARIA DEL SOCORRO GONZALEZ FIGUEROA | P29: PBRO. FELIPE DE JESUS ZARAGOZA ORTEGA | Q29: 610 | R29: =H29&" Y "&I29 -> ISMAEL GONZALEZ FIGUEROA Y TERESITA DE JESUS ALVAREZ PEREZ | S29: =D29&" "&E29&" DE "&F29 -> 2 ABRIL DE 2001 | T29: =J29&" "&K29&" DE "&L29 -> 3 ABRIL DE 2010 | U29: 1 | V29: 10 | W29: 20
A30: 21 | B30: ASHLEY REGINA HURTADO FELIX | D30: 7 | E30: AGOSTO | F30: 2009 | G30: HERMOSILLO, SONORA | H30: FRANCISCO GILBERTO HURTADO FELIX | I30: LILIANA BERENICE FELIX HERRERA | J30: 17 | K30: ABRIL | L30: 2010 | M30: PBRO. FELIPE DE JESUS ZARAGOZA ORTEGA | N30: ALFREDO FELIX REYES, LUCIA FELIX REYES Y ITZEL MARIA FELIX OROZCO | O30: LUIS FRANCO ACOSTA, EDITH ESPINOZA GONZALEZ Y FRANCISCO JAVIER VALDEZ JIMENEZ | P30: PBRO. FELIPE DE JESUS ZARAGOZA ORTEGA | Q30: 3087 | R30: =H30&" Y "&I30 -> FRANCISCO GILBERTO HURTADO FELIX Y LILIANA BERENICE FELIX HERRERA | S30: =D30&" "&E30&" DE "&F30 -> 7 AGOSTO DE 2009 | T30: =J30&" "&K30&" DE "&L30 -> 17 ABRIL DE 2010 | U30: 1 | V30: 11 | W30: 21
A31: 22 | B31: ESTEBAN RENE CASTRO GALINDO | D31: 12 | E31: SEPTIEMBRE | F31: 2008 | G31: HERMOSILLO, SONORA | H31: LUIS EFRAIN CASTRO VAZQUEZ | I31: TERESA ELIZABETH GALINDO AVITIA | J31: 25 | K31: ABRIL | L31: 2010 | M31: PBRO. FELIPE DE JESUS ZARAGOZA ORTEGA | N31: ALONSO FELIX Y ELIZABETH GALINDO MORENO | O31: JESUS RODRIQUEZ LASTRA Y ANA ELSA ALONSO FELIX | P31: PBRO. FELIPE DE JESUS ZARAGOZA ORTEGA | Q31: 4183 | R31: =H31&" Y "&I31 -> LUIS EFRAIN CASTRO VAZQUEZ Y TERESA ELIZABETH GALINDO AVITIA | S31: =D31&" "&E31&" DE "&F31 -> 12 SEPTIEMBRE DE 2008 | T31: =J31&" "&K31&" DE "&L31 -> 25 ABRIL DE 2010 | U31: 1 | V31: 11 | W31: 22
A32: 23 | B32: REGINA ROMERO GUERRERO | D32: 25 | E32: DICIEMBRE | F32: 2009 | G32: LOS MOCHIS, SINALOA | H32: JOSE ALFREDO ROMERO HOLGUIN | I32: TAVATA PRISCILLA GUERRERO PEÑUELS | J32: 1 | K32: MAYO | L32: 2010 | M32: PBRO. FELIPE DE JESUS ZARAGOZA ORTEGA | N32: JORGE ALBERTO ROMERO HOLGUIN Y DIANA PATRICIA RODELO HERNANDEZ | O32: LEV PAVEL AGUIRRE MORALES Y MILLY ROCHA M. | P32: PBRO. FELIPE DE JESUS ZARAGOZA ORTEGA | Q32: 568 | R32: =H32&" Y "&I32 -> JOSE ALFREDO ROMERO HOLGUIN Y TAVATA PRISCILLA GUERRERO PEÑUELS | S32: =D32&" "&E32&" DE "&F32 -> 25 DICIEMBRE DE 2009 | T32: =J32&" "&K32&" DE "&L32 -> 1 MAYO DE 2010 | U32: 1 | V32: 12 | W32: 23
A33: 24 | B33: CHRISTIAN PAUL MINJAREZ LEON | D33: 21 | E33: NOVIEMBRE | F33: 2009 | G33: HERMOSILLO, SONORA | H33: JULIO CESAR MINJAREZ SALAS | I33: CAROLINA LEON OROZ | J33: 1 | K33: MAYO | L33: 2010 | M33: PBRO. FELIPE DE JESUS ZARAGOZA ORTEGA | N33: MARCO ANTONIO MINJAREZ SALAS | O33: MARIA LUISA LEON OROZ | P33: PBRO. FELIPE DE JESUS ZARAGOZA ORTEGA | Q33: 3705 | R33: =H33&" Y "&I33 -> JULIO CESAR MINJAREZ SALAS Y CAROLINA LEON OROZ | S33: =D33&" "&E33&" DE "&F33 -> 21 NOVIEMBRE DE 2009 | T33: =J33&" "&K33&" DE "&L33 -> 1 MAYO DE 2010 | U33: 1 | V33: 12 | W33: 24
A34: 25 | B34: DANTE MINJAREZ VILLA | D34: 30 | E34: NOVIEMBRE | F34: 2009 | G34: HERMOSILLO, SONORA | H34: MARCO ANTONIO MINJAREZ ROSAS | I34: GUADALUPE VILLA RUBALCABA | J34: 1 | K34: MAYO | L34: 2010 | M34: PBRO. FELIPE DE JESUS ZARAGOZA ORTEGA | N34: MARCO ANTONIO MINJAREZ ROSAS | O34: MARIBEL VILLA RUBALCABA | P34: PBRO. FELIPE DE JESUS ZARAGOZA ORTEGA | Q34: 1698 | R34: =H34&" Y "&I34 -> MARCO ANTONIO MINJAREZ ROSAS Y GUADALUPE VILLA RUBALCABA | S34: =D34&" "&E34&" DE "&F34 -> 30 NOVIEMBRE DE 2009 | T34: =J34&" "&K34&" DE "&L34 -> 1 MAYO DE 2010 | U34: 1 | V34: 13 | W34: 25
A35: 26 | B35: PAULA LILIAN MERCADO SEAMAN | D35: 26 | E35: JUNIO | F35: 2009 | G35: HERMOSILLO, SONORA | H35: JUAN ENRIQUE A. MERCADO RUIZ | I35: NORMA LILIANA SEAMAN CHAIREZ | J35: 8 | K35: MAYO | L35: 2010 | M35: PBRO. FELIPE DE JESUS ZARAGOZA ORTEGA | N35: JUAN FRANCISCO NAVARRO RODRIGUEZ Y ADRIANA SEAMAN CHAIREZ | O35: GUSTAVO ZAMORANO BARRERAS Y YADIRA RUIZ AYON | P35: PBRO. FELIPE DE JESUS ZARAGOZA ORTEGA | Q35: 2782 | R35: =H35&" Y "&I35 -> JUAN ENRIQUE A. MERCADO RUIZ Y NORMA LILIANA SEAMAN CHAIREZ | S35: =D35&" "&E35&" DE "&F35 -> 26 JUNIO DE 2009 | T35: =J35&" "&K35&" DE "&L35 -> 8 MAYO DE 2010 | U35: 1 | V35: 13 | W35: 26
A36: 27 | B36: VALERIA CAMILA RAMIREZ PEÑA | D36: 28 | E36: AGOSTO | F36: 2008 | G36: HERMOSILLO, SONORA | H36: CLEMENTE ADITH RAMIREZ BARRETO | I36: FRANCISCA PEÑA TRUQUI | J36: 8 | K36: MAYO | L36: 2010 | M36: PBRO. FELIPE DE JESUS ZARAGOZA ORTEGA | N36: ELIZABETH RAMIREZ BARRETO | O36: ALEJANDRO LOPEZ RAMIREZ | P36: PBRO. FELIPE DE JESUS ZARAGOZA ORTEGA | Q36: 2864 | R36: =H36&" Y "&I36 -> CLEMENTE ADITH RAMIREZ BARRETO Y FRANCISCA PEÑA TRUQUI | S36: =D36&" "&E36&" DE "&F36 -> 28 AGOSTO DE 2008 | T36: =J36&" "&K36&" DE "&L36 -> 8 MAYO DE 2010 | U36: 1 | V36: 14 | W36: 27
A37: 28 | B37: MARIA IVANNA | D37: 4 | E37: MARZO | F37: 2010 | G37: HERMOSILLO, SONORA | H37: JOSE ANGEL COTA VELARDE | I37: ALEJANDRE GUADALUPE TAPIA BARRIOS | J37: 8 | K37: MAYO | L37: 2010 | M37: PBRO. FELIPE DE JESUS ZARAGOZA ORTEGA | N37: JOSE DAVID BIEBRICH GUEVARA Y CINTYA LORENA AGUAYO FERRE | O37: ELIOS CADENA AYOR Y ELIZABETH COTA DAVILA | P37: PBRO. FELIPE DE JESUS ZARAGOZA ORTEGA | Q37: 155 | R37: =H37&" Y "&I37 -> JOSE ANGEL COTA VELARDE Y ALEJANDRE GUADALUPE TAPIA BARRIOS | S37: =D37&" "&E37&" DE "&F37 -> 4 MARZO DE 2010 | T37: =J37&" "&K37&" DE "&L37 -> 8 MAYO DE 2010 | U37: 1 | V37: 14 | W37: 28
A38: 29 | B38: ESTEFANY DAVALOS FELIX | D38: 18 | E38: MAYO | F38: 2008 | G38: HERMOSILLO, SONORA | H38: JUAN CARLOS DAVALOS FLORES | I38: MIRIAM BEATRIZ FELIX ARMENTA | J38: 8 | K38: MAYO | L38: 2010 | M38: PBRO. FELIPE DE JESUS ZARAGOZA ORTEGA | N38: ALMA LILIANA DAVALOS FLORES | O38: ELIZABETH FELIX ARMENTA | P38: PBRO. FELIPE DE JESUS ZARAGOZA ORTEGA | Q38: 2260 | R38: =H38&" Y "&I38 -> JUAN CARLOS DAVALOS FLORES Y MIRIAM BEATRIZ FELIX ARMENTA | S38: =D37&" "&E38&" DE "&F38 -> 4 MAYO DE 2008 | T38: =J38&" "&K38&" DE "&L38 -> 8 MAYO DE 2010 | U38: 1 | V38: 15 | W38: 29
A39: 30 | B39: MIRANDA ALDAY MOORE | D39: 9 | E39: DICIEMBRE | F39: 2009 | G39: HERMOSILLO, SONORA | I39: MONICA ALDAY MOORE | J39: 8 | K39: MAYO | L39: 2010 | M39: PBRO. FELIPE DE JESUS ZARAGOZA ORTEGA | N39: EFREN ALDAY MOORE Y ALTAGRACIA ALDAY MOORE | O39: RAUL ALONSO BRQACAMONTES ALDAY Y LAURA DAINA NAVARRO SANDOVAL | P39: PBRO. FELIPE DE JESUS ZARAGOZA ORTEGA | Q39: 4979 | R39: =H39&" Y "&I39 -> Y MONICA ALDAY MOORE | S39: =D38&" "&E39&" DE "&F39 -> 18 DICIEMBRE DE 2009 | T39: =J39&" "&K39&" DE "&L39 -> 8 MAYO DE 2010 | U39: 1 | V39: 15 | W39: 30
A40: 31 | B40: VICTORIA AZUCENA TORRES CANO | D40: 5 | E40: DICIEMBRE | F40: 2009 | G40: HERMOSILLO, SONORA | H40: SAUL EUGENIO TORRES MILLAN | I40: CLAUDIA CANO VIVERO | J40: 22 | K40: MAYO | L40: 2010 | M40: PBRO. FELIPE DE JESUS ZARAGOZA ORTEGA | N40: ALEJANDRO TORRES CANO, SAUL ENRIQUE TORRES CANO | O40: EDGAR EDUARDO TORRES CANO | P40: PBRO. FELIPE DE JESUS ZARAGOZA ORTEGA | Q40: 59 | R40: =H40&" Y "&I40 -> SAUL EUGENIO TORRES MILLAN Y CLAUDIA CANO VIVERO | S40: =D39&" "&E40&" DE "&F40 -> 9 DICIEMBRE DE 2009 | T40: =J40&" "&K40&" DE "&L40 -> 22 MAYO DE 2010 | U40: 1 | V40: 16 | W40: 31
A41: 32 | B41: CARLOS MARCELO GUTIERREZ ALBRECHT | D41: 9 | E41: NOVIEMBRE | F41: 1977 | G41: HERMOSILLO, SONORA | H41: MODESTO NEPOMUSENO GUTIERREZ DIAZ | I41: GODINA ELVIRA ALBRECHT KALL | J41: 29 | K41: MAYO | L41: 2010 | M41: PBRO. FELIPE DE JESUS ZARAGOZA ORTEGA | N41: CARIDAD DEL CARMEN VENEGAS VEGA | O41: CARLOTA GABRIELA VENEGAS VEGA | P41: PBRO. FELIPE DE JESUS ZARAGOZA ORTEGA | Q41: 2254 | R41: =H41&" Y "&I41 -> MODESTO NEPOMUSENO GUTIERREZ DIAZ Y GODINA ELVIRA ALBRECHT KALL | S41: =D41&" "&E41&" DE "&F41 -> 9 NOVIEMBRE DE 1977 | T41: =J41&" "&K41&" DE "&L41 -> 29 MAYO DE 2010 | U41: 1 | V41: 16 | W41: 32
A42: 33 | B42: DIANE ANGELICA ROMERO AGUILAR | D42: 28 | E42: AGOSTO | F42: 2009 | G42: HERMOSILLO, SONORA | H42: OMAR CAIN ROMERO CASTRO | I42: ANGELICA MARIA AGUILAR BOJORQUEZ | J42: 29 | K42: MAYO | L42: 2010 | M42: PBRO. FELIPE DE JESUS ZARAGOZA ORTEGA | P42: PBRO. FELIPE DE JESUS ZARAGOZA ORTEGA | Q42: 3735 | R42: =H42&" Y "&I42 -> OMAR CAIN ROMERO CASTRO Y ANGELICA MARIA AGUILAR BOJORQUEZ | S42: =D42&" "&E42&" DE "&F42 -> 28 AGOSTO DE 2009 | T42: =J42&" "&K42&" DE "&L42 -> 29 MAYO DE 2010 | U42: 1 | V42: 17 | W42: 33
A43: 34 | B43: VALENTIN LOPEZ GAXIOLA | D43: 23 | E43: JUNIO | F43: 2009 | G43: HERMOSILLO, SONORA | I43: KARLA LOPEZ GAXIOLA | J43: 12 | K43: JUNIO | L43: 2010 | M43: PBRO. FELIPE DE JESUS ZARAGOZA ORTEGA | N43: FELIPE DE JESUS LOPEZ GAXIOLA | O43: MAIRA AURORA MENDIVIL HERNANDEZ | P43: PBRO. FELIPE DE JESUS ZARAGOZA ORTEGA | Q43: 1956 | R43: =H43&" Y "&I43 -> Y KARLA LOPEZ GAXIOLA | S43: =D43&" "&E43&" DE "&F43 -> 23 JUNIO DE 2009 | T43: =J43&" "&K43&" DE "&L43 -> 12 JUNIO DE 2010 | U43: 1 | V43: 17 | W43: 34
A44: 35 | B44: AYLINE KARIME HIGUERA LOPEZ | D44: 30 | E44: DICIEMBRE | F44: 2003 | G44: TUCSON, ARIZONA | H44: JOSE LINO HIGUERA ROMERO | I44: KARLA LOPEZ GAXIOLA | J44: 13 | K44: JUNIO | L44: 2010 | M44: PBRO. FELIPE DE JESUS ZARAGOZA ORTEGA | N44: JESUS ERNESTO LOPEZ GAXIOLA | O44: MARTHA YOLANDA MIRANDA MARTINEZ | P44: PBRO. FELIPE DE JESUS ZARAGOZA ORTEGA | Q44: 89986 | R44: =H44&" Y "&I44 -> JOSE LINO HIGUERA ROMERO Y KARLA LOPEZ GAXIOLA | S44: =D44&" "&E44&" DE "&F44 -> 30 DICIEMBRE DE 2003 | T44: =J44&" "&K44&" DE "&L44 -> 13 JUNIO DE 2010 | U44: 1 | V44: 18 | W44: 35
...

Sheet IMPRESION-CONSTANCIA DEBAUTISMO
A1: 2832
B3: 116
C4: =LOOKUP($A$1,CONSTANCIA.BAUTISMO!$A$99:B1156) -> ANDY TADEO TEQUIDA GALAZ
C5: =LOOKUP($A$1,CONSTANCIA.BAUTISMO!$A$99:$S$1156) -> 17 OCTUBRE DE 2022 | I5: =LOOKUP($A$1,CONSTANCIA.BAUTISMO!$A$99:$Q$1156) -> 1633
C6: =LOOKUP($A$1,CONSTANCIA.BAUTISMO!$A$99:$G$1156) -> HERMOSILLO, SONORA
C7: =LOOKUP($A$1,CONSTANCIA.BAUTISMO!$A$99:$R$1156) -> ESTEBAN TEQUIDA VILLALOBOS Y CRUZ YENI GALAZ GALAZ
C8: =LOOKUP($A$1,CONSTANCIA.BAUTISMO!$A$99:$N$1156) -> ERICK ALAIN GALAZ GALAZ
C9: =LOOKUP($A$1,CONSTANCIA.BAUTISMO!$A$99:$O$1156) -> CARMEN YULIANA ESTRADA GALAZ
E10: =LOOKUP($A$1,CONSTANCIA.BAUTISMO!$A$99:$T$1156) -> 17 DICIEMBRE DE 2022
C12: 1 | D12: Página 75 | H12: 149 | M12: Pagina
C14: =IF(LOOKUP($A$1,CONSTANCIA.BAUTISMO!$A$99:$M$1156)=0, " ",LOOKUP($A$1,CONSTANCIA.BAUTISMO!$A$99:$M$1156)) -> PBRO. GERARDO CAMACHO PONCE | H14: =IF(LOOKUP($A$1,CONSTANCIA.BAUTISMO!$A$99:$P$1156)=0, " ",LOOKUP($A$1,CONSTANCIA.BAUTISMO!$A$99:$P$1156)) -> PBRO. GERARDO CAMACHO PONCE

Sheet CATECUMENOS 
A1: CATECUMENOS VIGILIA PASCUAL 03 ABRIL 2021
A2: NOMBRE | B2: FECHA SACRAMENTO | E2: PADRE | F2: MADRE | G2: PADRINOS
A3: BRISSIA NAHOMY FLORES DE LEON | B3: 3 | C3: ABRIL | D3: 2021 | E3: JACOB SADRAC FLORES GRACIA | F3: MARLENE GPE. DE LEON RODRIGUEZ | G3: JOSÉ BENJAMIN RAYA GARCIA y MYRNA ADRIANA MARTÍNEZ ORTÍZ
A4: SOFÍA PERALTA ANDRADE | B4: 3 | C4: ABRIL | D4: 2021 | E4: RIGOBERTO PERALTA FELIX | F4: SANTA ISELA ANDRADE PARRA | G4: JOSÉ P. TANAKA ANDRADE y MARÍA DEL ROSARIO MATUZ ANDRADE
A5: BRAYAN ARNOLDO VALENZUELA VERDUGO | B5: 3 | C5: ABRIL | D5: 2021 | E5: ALICIA VALENZUELA VERDUGO | F5: ** **** ** **** *** **** | G5: ALBA ALICIA VALENZUELA VERDUGO
A6: MARÍA XIOMARA GUADALUPE BOULLET OCHOA | B6: 3 | C6: ABRIL | D6: 2021 | E6: VIANCA SUGEY BOULLET OCHOA | F6: ** *** **** ** **** **** | G6: JOSÉ GPE. LÓPEZ TRUJILLO y BRIANDA YAQUELIN BAULLET OCHOA
