Workbook
Name A: '1ra.COMUNION'!#REF!
Name A: '1ra.COMUNION'!#REF!
Name DIA: '1ra.COMUNION'!#REF!
Name DIA: BAUTIZMO!#REF!
Name DIA: [1]MATRIMONIO!#REF!
Name DIA: MATRIMONIO!#REF!
Name DIA: MATRIMONIO!#REF!
Name DIA: [1]MATRIMONIO!#REF!
Name DIA: MATRIMONIO!#REF!

Sheet MATRIMONIO
B3: CERTIFICADO DE MATRIMONIO 2023
B4: PAREJA | C4: DIA | D4: MES | E4: AÑO | F4: PRESBITERO | G4: TESTIGO1 | H4: TESTIGO2 | I4: TESTIGO3 | J4: TESTIGO4 | K4: PÁRROCO | L4: LIBRO | M4: PAGINA | N4: PARTIDA | V4: Dias | W4: Mes
A5: 1 | B5: FILIBERTO GERARDO Y CLAUDIA VIRIDIANA | C5: 25 | D5: MARZO | E5: 2023 | F5: GERARDO CAMACHO PONCE | G5: ERIKA GABRIELA BETANCOURT HERNANDEZ | H5: RAMON HUARAQUI ROMERO | I5: ROSA ISELA GUTIERREZ ARCE | J5: RAFAEL MEDINA CARDENAS | K5: PBRO. GERARDO CAMACHO PONCE | L5: 1 | M5: 32 | N5: 63 | V5: 1 | W5: ENERO
A6: 2 | B6: RAMON ENRIQUE Y CLAUDIA IXCHEL | C6: 26 | D6: MAYO | E6: 2023 | F6: CESAR ZAID CHUFFE BRITO | G6: MARCO VINICIO VEGA LOPEZ | H6: MONICA MORALES RODRIGUEZ | I6: JESUS JOEL TREJO OCHOA | J6: LEONOR CONTRERAS DE TREJO | K6: PBRO. GERARDO CAMACHO PONCE | L6: 1 | M6: 32 | N6: 64 | V6: 2 | W6: FEBRERO
A7: 3 | B7: VICTOR MANUEL E ISABEL | C7: 5 | D7: AGOSTO | E7: 2023 | F7: GERARDO CAMACHO PONCE | G7: FAUSTINO DE JESUS CHAIDEZ BELTRAN | H7: JIMENA ISABEL BETANCOURT VILLALOBOS | I7: MARGARITA VELAZQUEZ ALFARO | J7: MELANY ATHZIRI BETANCOURT VILLALOBOS | K7: PBRO. GERARDO CAMACHO PONCE | L7: 1 | M7: 33 | N7: 65 | V7: 3 | W7: MARZO
A8: 4 | B8: MANUEL GONZALO Y MARIA VERONICA | C8: 14 | D8: OCTUBRE | E8: 2023 | F8: GERARDO CAMACHO PONCE | G8: BRYAN ALEXIS BOURGOIN GRAJEDA | H8: MANUEL GONZALO BOURGOIN GRAJEDA | I8: SEGIO ENRIQUE CASTAÑEDA GUERRERO | J8: ARATH ADAL BOURGOIN GRAJEDA | K8: PBRO. GERARDO CAMACHO PONCE | L8: 1 | M8: 33 | N8: 66 | V8: 4 | W8: ABRIL
A9: 5 | B9: GUADALUPE MARTIN Y RAFAELA | C9: 28 | D9: OCTUBRE | E9: 2023 | F9: ERICK BENJAMIN DOMINGUEZ DUARTE | G9: MARGARITA PINELA CASTAÑEDA | H9: JOSE ANGEL GUERRERO ALVAREZ | I9: ALEJANDRA BUZANI ESPARZA | J9: DIEGO ENRIQUE FRANCO JASSO | K9: PBRO. GERARDO CAMACHO PONCE | L9: 1 | M9: 34 | N9: 67 | V9: 5 | W9: MAYO
A10: 6 | B10: FRANCISCO ENRIQUE Y DANIELA ALEJANDRA | C10: 25 | D10: NOVIEMBRE | E10: 2023 | F10: PBRO. CARLOS SANTIAGO ROBLES URREA | G10: RAMIRO GERMAN GANDARILLA | H10: VERONICA MONGUEL LOPEZ | I10: OSCAR ARMANDO MUNGUIA ALCALA | J10: LAURA MARTINEZ VALENZUELA | K10: PBRO. GERARDO CAMACHO PONCE | L10: 1 | M10: 34 | N10: 68 | V10: 6 | W10: JUNIO
B11: CERTIFICADO DE MATRIMONIO 2024
A12: 7 | B12: RENE ALEXANDER Y ANA LAURA | C12: 19 | D12: ABRIL | E12: 2024 | F12: GERARDO CAMACHO PONCE | G12: MERCED LOPEZ NAVA | H12: ANA LUZ COVARRUBIAS FLORES | I12: KARINA ALBINA CAMARGO TORRES | J12: MARIA DE LOS ANGELES TORRES PEREZ | K12: PBRO. GERARDO CAMACHO PONCE | L12: 1 | M12: 35 | N12: 69 | V12: 7 | W12: JULIO
A13: 8 | B13: CARLOS OMAR Y DENIA DEL CARMEN | C13: 20 | D13: ABRIL | E13: 2024 | F13: GERARDO CAMACHO PONCE | G13: FELIPE DE JESUS ALCALA | H13: OLGA RIOS MORALES | I13: BALDEMAR NORIEGA VASQUEZ | J13: ANA ALICIA RUIZ BURREL | K13: PBRO. GERARDO CAMACHO PONCE | L13: 1 | M13: 35 | N13: 70 | V13: 8 | W13: AGOSTO
A14: 9 | B14: FERNANDO FRANCISCO Y EDNA PATRICIA | C14: 27 | D14: ABRIL | E14: 2024 | F14: GERARDO CAMACHO PONCE | G14: RAFAEL EDUARDO MENDIVIL RAMIREZ | H14: ROSARIO BUELNA MENDIVIL | I14: HERIBERTO TAPIA FLORES | J14: ANA IRIS GALINDO QUINTANA | K14: PBRO. GERARDO CAMACHO PONCE | L14: 1 | M14: 36 | N14: 71 | V14: 9 | W14: SEPTIEMBRE
A15: 10 | B15: PAVEL Y DOLORES FABIOLA | C15: 27 | D15: SEPTIEMBRE | E15: 2024 | F15: GERARDO CAMACHO PONCE | G15: ANA VERONICA PARRA COLORES | H15: NATALY PEÑA BERNAL | I15: YADIRA GUADALUPE PARRA COLORES | J15: FRANCISCA LUKSO | K15: PBRO. GERARDO CAMACHO PONCE | L15: 1 | M15: 36 | N15: 72 | V15: 10 | W15: OCTUBRE
A16: 11 | B16: OCTAVIO Y DANIELA | C16: 20 | D16: OCTUBRE | E16: 2024 | F16: GERARDO CAMACHO PONCE | G16: SALVADOR FLORES SOTO | H16: PATRICIA ACOSTA QUEZADA | I16: MIGUEL ANGEL MUÑOZ | J16: IRAZEMA J. GONZALEZ DE MUÑOZ | K16: PBRO. GERARDO CAMACHO PONCE | L16: 1 | M16: 37 | N16: 73 | V16: 11 | W16: NOVIEMBRE
A17: 12 | B17: JORGE ALBERTO Y LILIANA CAROLINA | C17: 8 | D17: NOVIEMBRE | E17: 2024 | F17: GERARDO CAMACHO PONCE | G17: JESUS FERNANDO ALDECOA CORDOVA | H17: SONYA MARIBEL CAMPOY GAMEZ | I17: RAMON ALFONSO VILLA NEVAREZ | J17: MARCELA MARTINEZ MUÑOZ | K17: PBRO. GERARDO CAMACHO PONCE | L17: 1 | M17: 37 | N17: 74 | V17: 12 | W17: DICIEMBRE
A18: 13 | B18: GABRIEL REFUGIO Y ERIKA GUADALUPE | C18: 30 | D18: NOVIEMBRE | E18: 2024 | F18: GERARDO CAMACHO PONCE | G18: ISMAEL SEPULVEDA SOLIS | H18: OFELIA DURAZO ZAMORA | I18: JAVIER VILLARREAL LOPEZ | J18: BEATRIZ GASCA SANCHEZ | K18: PBRO. GERARDO CAMACHO PONCE | L18: 1 | M18: 38 | N18: 75 | V18: 13
A19: 14 | B19: FRANCISCO JAVIER Y MARIA DOLORES | C19: 7 | D19: DICIEMBRE | E19: 2024 | F19: GERARDO CAMACHO PONCE | G19: ISMAEL HORACIO ASSALIA JACOTT | H19: ANA YAMMILETH CASAS ANDRADE | I19: MANUEL ELIAS MERCADO ALVARADO | J19: PATRICIA GUADALUPE NAVARRO ROBLES | K19: PBRO. GERARDO CAMACHO PONCE | L19: 1 | M19: 38 | N19: 76 | V19: 14
B20: CERTIFICADO DE MATRIMONIO 2025
A21: 15 | B21: MARTIN Y GLORIA PAZ | C21: 19 | D21: FEBRERO | E21: 2025 | F21: GERARDO CAMACHO PONCE | G21: HECTOR MARTINEZ GARCIA | H21: MARIA DE LOS ANGELES LOPEZ GIL | I21: LUIS FRANCISCO DEL REAL VEGA | J21: OFELIA BARRAZA HOYOS | K21: PBRO. GERARDO CAMACHO PONCE | L21: 1 | M21: 39 | N21: 77 | V21: 15
A22: 16 | B22: MARTIN GUILLERMO Y MIRZA | C22: 8 | D22: MARZO | E22: 2025 | F22: GERARDO CAMACHO PONCE | G22: MIGUEL ANGEL DUARTE ROJAS | H22: GRISELDA BETZABETH FELIX ORTIZ | I22: JOSE ANTONIO VEGA | J22: ALEJANDRA VEGA | K22: PBRO. GERARDO CAMACHO PONCE | L22: 1 | M22: 39 | N22: 78 | V22: 16
A23: 17 | B23: ISAAC Y PERLA KARITZA | C23: 26 | D23: ABRIL | E23: 2025 | F23: PBRO. CARLOS SANTIAGO ROBLES URREA | G23: LUIS MATIAS DE LA VARA ROBLES | H23: LAURA ELENA GRIJALVA HARO | I23: ARTUTO ANASTACIO REYNA CASTRO | J23: ANABEL SOLORZANO DREW | K23: PBRO. GERARDO CAMACHO PONCE | L23: 1 | M23: 40 | N23: 79 | V23: 17
A24: 18 | B24: MARTIN ABRAHAM Y THANAIRI | C24: 6 | D24: JUNIO | E24: 2025 | F24: GERARDO CAMACHO PONCE | G24: MARTIN ESPINOZA MEDINA | H24: JOSEFINA SOTO ESCALANTE | I24: RICARDO GONZALEZ GRIJALVA | J24: ALMA VERONICA LOBIO VIZCARRA | K24: PBRO. GERARDO CAMACHO PONCE | L24: 1 | M24: 40 | N24: 80 | V24: 18
A25: 19 | B25: CARLOS ADRIAN Y ANGELICA DE LOURDES | C25: 19 | D25: DICIEMBRE | E25: 2025 | F25: GERARDO CAMACHO PONCE | G25: JORGE RAMIREZ JIMENEZ | H25: LUISA FERNANDA RUIZ CAZARES | I25: HORACIO BALDERRAMA COTA | J25: MAYRA ARENAS MONGE | K25: PBRO. GERARDO CAMACHO PONCE | L25: 1 | M25: 41 | N25: 81 | V25: 19
A26: 20 | B26: GUADALUPE DE JESUS Y MERARI ABIGAIL | C26: 27 | D26: DICIEMBRE | E26: 2025 | F26: GERARDO CAMACHO PONCE | G26: RAUL SALVADOR MARTINEZ VILLA | H26: BEATRIZ ELENA SALAZAR ESPARZA | I26: JOAQUIN CRUZ GRIJALVA | J26: ALMA IRENE VALENZUELA JIMENEZ | K26: PBRO. GERARDO CAMACHO PONCE | L26: 1 | M26: 41 | N26: 82 | V26: 20
B27: CERTIFICADO DE MATRIMONIO 2026
A28: 21 | B28: JESUS MANUEL Y DENISE SARAHI | C28: 18 | D28: ABRIL | E28: 2026 | F28: GERARDO CAMACHO PONCE | G28: GERARDO VALENZUELA VARELA | H28: TERESITA OCTAVIANA JUSAINO MONGE | I28: JUAN PALAFOX LUNA | J28: BLANCA ALICIA IBARRA MENDOZA | K28: PBRO. GERARDO CAMACHO PONCE | L28: 1 | M28: 42 | N28: 83 | V28: 22
A29: 22 | K29: PBRO. GERARDO CAMACHO PONCE | L29: 1 | M29: 42 | N29: 84 | V29: 23
A30: 23 | K30: PBRO. GERARDO CAMACHO PONCE | L30: 1 | M30: 43 | N30: 85 | V30: 24
A31: 24 | K31: PBRO. GERARDO CAMACHO PONCE | L31: 1 | M31: 43 | N31: 86 | V31: 25
A32: 25 | K32: PBRO. GERARDO CAMACHO PONCE | L32: 1 | M32: 44 | N32: 87 | V32: 26
A33: 26 | K33: PBRO. GERARDO CAMACHO PONCE | L33: 1 | M33: 44 | N33: 88 | V33: 27
A34: 27 | K34: PBRO. GERARDO CAMACHO PONCE | L34: 1 | M34: 45 | N34: 89 | V34: 28
A35: 28 | M35: 45 | N35: 90 | V35: 29
A36: 29 | V36: 30
A37: 30 | V37: 31
A38: 31
A39: 32
A40: 33
A41: 34
A42: 35
...

Sheet IMPRESION-MATRIMONIO
A1: 21
C3: =LOOKUP($A$1,MATRIMONIO!$A$5:B965) -> JESUS MANUEL Y DENISE SARAHI
D7: =IF(LOOKUP($A$1,MATRIMONIO!$A$5:C965)=0," ",LOOKUP($A$1,MATRIMONIO!$A$5:C965)) -> 18 | F7: =IF(LOOKUP($A$1,MATRIMONIO!$A$5:D965)=0," ",LOOKUP($A$1,MATRIMONIO!$A$5:D965)) -> ABRIL | I7: =IF(LOOKUP($A$1,MATRIMONIO!$A$5:E965)=0," ",LOOKUP($A$1,MATRIMONIO!$A$5:E965)) -> 2026 | L7: =IF(LOOKUP($A$1,MATRIMONIO!$A$5:F965)=0," ",LOOKUP($A$1,MATRIMONIO!$A$5:F965)) -> GERARDO CAMACHO PONCE
C9: =IF(LOOKUP($A$1,MATRIMONIO!$A$5:G965)=0," ",LOOKUP($A$1,MATRIMONIO!$A$5:G965)) -> GERARDO VALENZUELA VARELA | K9: =LOOKUP($A$1,MATRIMONIO!$A$5:H965) -> TERESITA OCTAVIANA JUSAINO MONGE
C11: =IF(LOOKUP($A$1,MATRIMONIO!$A$5:I965)=0," ",LOOKUP($A$1,MATRIMONIO!$A$5:I965)) -> JUAN PALAFOX LUNA | K11: =IF(LOOKUP($A$1,MATRIMONIO!$A$5:I965)=0," ",LOOKUP($A$1,MATRIMONIO!$A$5:J965)) -> BLANCA ALICIA IBARRA MENDOZA
F13: =LOOKUP($A$1,MATRIMONIO!$A$5:L965) -> 1 | I13: =LOOKUP($A$1,MATRIMONIO!$A$5:M965) -> 42
F14: =LOOKUP($A$1,MATRIMONIO!$A$5:N965) -> 83 | L14: PBRO. GERARDO CAMACHO
C20: NOTA: SOLO TECLEAR EN LA COLUMNA A1 EL NUMERO CORRESPONDA EN LA HOJA MATRIMONIO

Sheet 1ra.COMUNION
C3: CERTIFICADO DE PRIMERA COMUNION 2023
R5: 1 | S5: ENERO
C6: JESUS EL SEÑOR - CARMEN CONTRERAS - 26 DE MAYO
C7: NIÑO(A) | D7: DIA | E7: MES | F7: AÑO | G7: PAPA | H7: MAMA | I7: MADRINA O PADRINO | J7: PÁRROCO
A8: 1 | B8: 1 | C8: EDYLET NATALIA BARRERAS ZARATE | D8: 26 | E8: MAYO | F8: 2023 | G8: EDUARDO BARRERAS MORALES | H8: SONIA LETICIA ZARATE QUIJADA | I8: VERONICA MARIA ZARATE QUIJADA | J8: PBRO. GERARDO CAMACHO PONCE
A9: 2 | B9: 2 | C9: CAMILA MEDRANO DUSTEN | D9: 26 | E9: MAYO | F9: 2023 | G9: ALEJANDRO MEDRANO ROJO | H9: DENISSE IZVETH DUSTEN GURROLA | I9: MANUEL DE JESUS DUSTEN LOPEZ Y JESUS DOLORES GURROLA PERAZA | J9: PBRO. GERARDO CAMACHO PONCE
A10: 3 | B10: 3 | C10: PAULINA GRACIA MARTINEZ | D10: 26 | E10: MAYO | F10: 2023 | G10: OSVALDO GUADALUPE GRACIA NORIEGA | H10: ALEJANDRA MARTINEZ NUÑEZ | I10: MARIA LUISA DUARTE MIRANDA | J10: PBRO. GERARDO CAMACHO PONCE
A11: 4 | B11: 4 | C11: DILBERT OJEDA IBARRA | D11: 26 | E11: MAYO | F11: 2023 | G11: JOSE LUIS OJEDA ALCANTAR | H11: JAZMIN MONICA IBARRA DELGADO | I11: ESTEBAN CHAZARO RAMIREZ Y ANA VICTORIA IBARRA DELGADO | J11: PBRO. GERARDO CAMACHO PONCE
A12: 5 | B12: 5 | C12: IKER SANTIAGO GARCIA OROZCO | D12: 26 | E12: MAYO | F12: 2023 | G12: RODRIGO GARCIA CONTRERAS | H12: PERLA AZUCENA OROZCO LIMON | I12: MIGUEL IVAN OROZCO LIMON | J12: PBRO. GERARDO CAMACHO PONCE
A13: 6 | B13: 6 | C13: ANA ELISA FERNANDEZ DAVILA | D13: 26 | E13: MAYO | F13: 2023 | G13: HECTOR EFRAIN FERNANDEZ LOZANO | H13: ADRIANA CECILIA DAVILA GUTIERREZ | I13: CRISTINA FERNANDEZ LOZANO | J13: PBRO. GERARDO CAMACHO PONCE
A14: 7 | B14: 7 | C14: MARIA BARBARA FERNANDEZ DAVILA | D14: 26 | E14: MAYO | F14: 2023 | G14: HECTOR EFRAIN FERNANDEZ LOZANO | H14: ADRIANA CECILIA DAVILA GUTIERREZ | I14: MARIA ALEJANDRA ARAIZA ARMENTA | J14: PBRO. GERARDO CAMACHO PONCE
A15: 8 | B15: 8 | C15: LUIS ALFONSO ACOSTA NUÑEZ | D15: 26 | E15: MAYO | F15: 2023 | G15: DANIEL ALFONSO ACOSTA ANTUNEZ | H15: ADARIT NUÑEZ CAMACHO | I15: DANIELA ACOSTA NUÑEZ | J15: PBRO. GERARDO CAMACHO PONCE
A16: 9 | B16: 9 | C16: ESTRELLA NAVARRO CAMACHO | D16: 26 | E16: MAYO | F16: 2023 | G16: PAUL ARTURO NAVARRO RAZCON | H16: ANA JAZLIM CAMACHO ESTRELLA | I16: LORENIA NAVARRO MENDOZA | J16: PBRO. GERARDO CAMACHO PONCE
A17: 10 | B17: 10 | C17: DAVID MARTIN VAZQUEZ LOPEZ | D17: 26 | E17: MAYO | F17: 2023 | G17: MARTIN GUASTAVO VAZQUEZ PALMA | H17: CLAUDIA FRANCISCA LOPEZ LEAL | I17: ABEL CAIN CARRANZA JIMENEZ Y ROSA MARIA RUIZ TRUJILLO | J17: PBRO. GERARDO CAMACHO PONCE
A18: 11 | B18: 11 | C18: SILVANA ALVARADO GOMEZ | D18: 26 | E18: MAYO | F18: 2023 | G18: EDUARDO ALVARADO PARTIDA | H18: MARCELA GOMEZ RAMOS | I18: XIMENA ALVARADO GOMEZ | J18: PBRO. GERARDO CAMACHO PONCE
A19: 12 | B19: 12 | C19: LEONARDO ORTEGA LERMA | D19: 26 | E19: MAYO | F19: 2023 | G19: JUAN CARLOS ORTEGA ABASOLO | H19: MARJORIE LERMA REYES | I19: MARIA DEL ROSARIO ORTEGA ABASOLO | J19: PBRO. GERARDO CAMACHO PONCE
... A29: 22 | B29: 22 | C29: PABLO ESCUDERO RODRIGUEZ | D29: 26 | E29: MAYO | F29: 2023 | G29: SERGIO ANTONIO ESCUDERO LUNA | H29: EUGENIA RODRIGUEZ VELASCO | I29: MONICA ARMIDA VELASCO MOLINA | J29: PBRO. GERARDO CAMACHO PONCE
C31: SAN PIO - ICELA CALDERA - 13 DE MAYO
C32: NIÑO(A) | D32: DIA | E32: MES | F32: AÑO | G32: PAPA | H32: MAMA | I32: MADRINA O PADRINO | J32: PÁRROCO
A33: 1 | B33: 23 | C33: ERIK SANTIAGO AYALA ORTA | D33: 13 | E33: MAYO | F33: 2023 | G33: JESUS IVAN AYALA GOMEZ | H33: CINTIA SELENE ORTA ARAIZA | I33: JESUS ALAN ORTA ARAIZA | J33: PBRO. GERARDO CAMACHO PONCE
A34: 2 | B34: 24 | C34: MARIANA GUADALUPE BARAJAS CASTAÑEDA | D34: 13 | E34: MAYO | F34: 2023 | G34: MARCO ANTONIO BARAJAS CORONADO | H34: FRANCISCA EDITH CASTAÑEDA SALAZAR | I34: MICHELLE ESMERALDA RODRIGUEZ SALAZAR | J34: PBRO. GERARDO CAMACHO PONCE
A35: 3 | B35: 25 | C35: DANIEL ALEXANDER BORBON GARDUÑO | D35: 13 | E35: MAYO | F35: 2023 | G35: FREDY BORBON ORTEGA | H35: MARIA DOLORES GARDUÑO REYES | I35: RAMON EMILIO NIEBLAS NORIEGA Y JESUS ALONDRA BORBON ENCINAS | J35: PBRO. GERARDO CAMACHO PONCE
A36: 4 | B36: 26 | C36: DEVANY BEATRIZ BRAVO PALAFOX | D36: 13 | E36: MAYO | F36: 2023 | G36: GILDARDO RUBEN BRAVO BADILLA | H36: EDUWIGES PALAFOX AGUIRRE | I36: MARIA INES PALAFOX AGUIRRE | J36: PBRO. GERARDO CAMACHO PONCE
A37: 5 | B37: 27 | C37: DAMIAN ALEXIS BUSTAMANTE RAMOS | D37: 13 | E37: MAYO | F37: 2023 | G37: JESUS GUADALUPE BUSTAMANTE DORADO | H37: CLAUDIA ADILENE RAMOS LUNA | I37: JUAN RAMOS LUNA | J37: PBRO. GERARDO CAMACHO PONCE
A38: 6 | B38: 28 | C38: SARAHI DEL CARMEN LOPEZ MORA | D38: 13 | E38: MAYO | F38: 2023 | G38: JESUS ALBERTO LOPEZ GARCIA | H38: MARIA DEL CARMEN MORA VILLALOBOS | I38: MARISOL GUADALUPE MORA VILLALOBOS | J38: PBRO. GERARDO CAMACHO PONCE
A39: 7 | B39: 29 | C39: SEBASTIAN ABELARDO LUNA MENDEZ | D39: 13 | E39: MAYO | F39: 2023 | G39: MARIO ALBERTO LUNA RODRIGUEZ | H39: SANDRA MARIA MENDEZ VAZQUEZ | I39: JUAN ANGEL DOMINGUEZ MENDEZ | J39: PBRO. GERARDO CAMACHO PONCE
A40: 8 | B40: 30 | C40: XIMENA ESTEFANIA MADA GARDUÑO | D40: 13 | E40: MAYO | F40: 2023 | G40: JOSE FRANCISCO MADA RAMIREZ | H40: MARIBEL GARDUÑO REYES | I40: YAILIN GARDUÑO REYES | J40: PBRO. GERARDO CAMACHO PONCE
A41: 9 | B41: 31 | C41: DARISSA BANELY MATA ORDUÑO | D41: 13 | E41: MAYO | F41: 2023 | G41: LUIS MANUEL MATA HERNANDEZ | H41: ROSA ALICIA GUADALUPE ORDUÑO BANDA | I41: BRAYAN ELEAZAR ORDUÑO BANDA Y MARIA INES PALAFOX AGUIRRE | J41: PBRO. GERARDO CAMACHO PONCE
A42: 10 | B42: 32 | C42: CARLOS JAVIER MOLINA SOTO | D42: 13 | E42: MAYO | F42: 2023 | G42: CARLOS JAVIER MOLINA HERMOSILLO | H42: CLAUDIA JUDITH SOTO PASILLAS | I42: YADIRA DEL REFUGIO HERMOSILLO REY | J42: PBRO. GERARDO CAMACHO PONCE
A43: 11 | B43: 33 | C43: SOFIA JAQUELINE MORALES PERALTA | D43: 13 | E43: MAYO | F43: 2023 | G43: JAZIEL CHAYAN MORALES GUZMAN | H43: TANIA JAQUELINE PERALTA FELIX | I43: FERNANDA ALEJANDRA RODRIGUEZ PERALTA | J43: PBRO. GERARDO CAMACHO PONCE
A44: 12 | B44: 34 | C44: ANGEL ISRAEL PEREZ ULIBARRIA | D44: 13 | E44: MAYO | F44: 2023 | G44: ISRAEL PEREZ ARAGON | H44: MARTINA ULIBARRIA SARABIA | I44: CARLOS REINALDO ALVARES GIRON Y EUFROCINA CABRERA PEREZ | J44: PBRO. GERARDO CAMACHO PONCE
A45: 13 | B45: 35 | C45: LLUVIA RUELAS MEZA | D45: 13 | E45: MAYO | F45: 2023 | H45: LLUVIA GUADALUPE RUELAS MEZA | I45: MARIA ISELA DE LA CRUZ | J45: PBRO. GERARDO CAMACHO PONCE
A46: 14 | B46: 36 | C46: MARIA JOSE AGUIRRE LOPEZ | D46: 13 | E46: MAYO | F46: 2023 | H46: VERONICA BEATRIZ AGUIRRE LOPEZ | I46: GILDARDO RUBEN BRAVO BADILLA | J46: PBRO. GERARDO CAMACHO PONCE
A47: 15 | B47: 37 | C47: SERGIO TADEO BADACHI MALDONADO | D47: 13 | E47: MAYO | F47: 2023 | G47: JOSE ABRAHAM BADACHI RODRIGUEZ | H47: KARINA HODERAY MALDONADO CAREAGA | I47: GUADALUPE LORENZO GAMEZ RIVAS Y MARIA AUXILIADORA BADACHI RODRIGUEZ | J47: PBRO. GERARDO CAMACHO PONCE
A48: 16 | B48: 38 | C48: MAYRIM CAMILA BARAJAS CASTAÑEDA | D48: 13 | E48: MAYO | F48: 2023 | G48: MARCO ANTONIO BARAJAS CORONADO | H48: FRANCISCA EDITH CASTAÑEDA SALAZAR | I48: GUADALUPE ANAHI RODRIGUEZ SALAZAR | J48: PBRO. GERARDO CAMACHO PONCE
A49: 17 | B49: 39 | C49: JAZMIN ALEJANDRA CORRALES MENDOZA | D49: 13 | E49: MAYO | F49: 2023 | G49: REY DAVID CORRALES RODRIGUEZ | H49: REYNA ALEJANDRA MENDOZA VALENZUELA | I49: ORALIA GUILLERMINA MENDOZA VALENZUELA | J49: PBRO. GERARDO CAMACHO PONCE
A50: 18 | B50: 40 | C50: JULIETH GUADALUPE MORENO SILVA | D50: 13 | E50: MAYO | F50: 2023 | G50: MARCOS ORLANDO MORENO ALBARRAN | H50: FERNANDA JAQUELINE SILVA SESMA | I50: MIRIAM LIZBETH BORJA RESENDEZ | J50: PBRO. GERARDO CAMACHO PONCE
A51: 19 | B51: 41 | C51: MARIA DEL SOL NAVA IBARRA | D51: 13 | E51: MAYO | F51: 2023 | G51: JESUS FRANCISCO NAVA POMPA | H51: REYNA JUDITH IBARRA MEDINA | I51: MARIA DELIA IBARRA MEDINA | J51: PBRO. GERARDO CAMACHO PONCE
A52: 20 | B52: 42 | C52: DORIAN ALBERTO OSUNA RODRIGUEZ | D52: 13 | E52: MAYO | F52: 2023 | G52: ALBERTO OSUNA MURILLO | H52: MARIA LIZBETH RODRIGUEZ MONGE | I52: FRANCISCA MONGE TARAZON | J52: PBRO. GERARDO CAMACHO PONCE
A53: 21 | B53: 43 | C53: BRITHANY GUADALUPE OZUNA BORJA | D53: 13 | E53: MAYO | F53: 2023 | G53: MARIO ARMANDO OZUNA MENDIVIL | H53: MIRIAM LIZBETH BORJA RESENDEZ | I53: IRMA ALICIA OZUNA MENDIVIL | J53: PBRO. GERARDO CAMACHO PONCE
...

Sheet IMPRESION-COMUNION
A1: 576
C6: =LOOKUP($A$1,'1ra.COMUNION'!$B$5:C3010) -> MIRANDA SAYURI ARCE LOPEZ
D8: =IF(LOOKUP($A$1,'1ra.COMUNION'!$B$5:D3010)=0," ",LOOKUP($A$1,'1ra.COMUNION'!$B$5:G3010)) -> JORGE ROGELIO ARCE DE LA ROSA | I8: =IF(LOOKUP($A$1,'1ra.COMUNION'!$B$5:H3010)=0," ",LOOKUP($A$1,'1ra.COMUNION'!$B$5:H3010)) -> SAYURI GABRIELA LOPEZ DURAN
G9: =LOOKUP(A1,'1ra.COMUNION'!B5:D3010) -> 30 | I9: =LOOKUP(A1,'1ra.COMUNION'!B5:E3010) -> MAYO | M9: =LOOKUP(A1,'1ra.COMUNION'!B5:F3010) -> 2026
C12: =LOOKUP($A$1,'1ra.COMUNION'!$B$5:I3010) -> ANGELA PADILLA VIRGEN
I14: =LOOKUP($A$1,'1ra.COMUNION'!$B$5:J3010) -> PBRO. GERARDO CAMACHO PONCE
C20: NOTA: SOLO TECLEAR EN LA COLUMAN A1 EL NUMERO CORRESPONDA EN LA HOJA 1ra.COMUNION

Sheet CONFIRMACION
B3: CERTIFICADO DE CONFIRMACION 2023
B4: CEDE PARROQUIA NSPAZ
B5: NTRA SRA DE LA PAZ - MARIBEL RODRIGUEZ
B6: NIÑA O NIÑO | C6: DIA | D6: MES | E6: AÑO | F6: PAPA | G6: MAMA | H6: MADRINA O PADRINO | I6: ARZOBISPO | J6: PARROCO | K6: LIBRO | L6: PAGINA | M6: PARTIDA
A7: 1 | B7: ALEXA URIAS HARO | C7: 21 | D7: JUNIO | E7: 2023 | F7: JOSE ALBERTO URIAS ESTRELLA | G7: LUZ AURORA HARO PESQUEIRA | H7: MARIA MARCELA ESTRELLA RAMIREZ | I7: RUY RENDON LEAL | J7: GERARDO CAMACHO PONCE | K7: 3 | L7: 9 | M7: 18
A8: 2 | B8: ANGEL IRAM QUIHUIS RODRIGUEZ | C8: 21 | D8: JUNIO | E8: 2023 | F8: HERIBERTO QUIHUIS CHAIREZ | G8: MARIA DOLORES RODRIGUEZ GOLDEN | H8: SANDRA LUZ SOTO | I8: RUY RENDON LEAL | J8: GERARDO CAMACHO PONCE | K8: 3 | L8: 10 | M8: 19
A9: 3 | B9: DANNA PAULA SALAS NAVARRO | C9: 21 | D9: JUNIO | E9: 2023 | F9: JOSE LUIS SALAS PONCE | G9: ELOINA NAVARRO AVILA | H9: SANDRA LUZ NAVARRO AVILA | I9: RUY RENDON LEAL | J9: GERARDO CAMACHO PONCE | K9: 3 | L9: 10 | M9: 20
A10: 4 | B10: DIEGO BOTELLO MENDEZ | C10: 21 | D10: JUNIO | E10: 2023 | F10: MIGUEL BOTELLO ARAUJO | G10: MARCELA MENDEZ BALDERRAMA | H10: NOEL ALEJANDRO SANCHEZ ESTRADA | I10: RUY RENDON LEAL | J10: GERARDO CAMACHO PONCE | K10: 3 | L10: 11 | M10: 21
A11: 5 | B11: FERNANDO ARTURO LOPEZ MONTAÑO | C11: 21 | D11: JUNIO | E11: 2023 | F11: LUIS FERNANDO LOPEZ PEÑA | G11: SONIA MONTAÑO DAVILA | H11: LUIS ENRIQUE VERDUGO TOLEDO | I11: RUY RENDON LEAL | J11: GERARDO CAMACHO PONCE | K11: 3 | L11: 11 | M11: 22
A12: 6 | B12: GABRIEL ALEJANDRO LOPEZ GARCIA | C12: 21 | D12: JUNIO | E12: 2023 | F12: GABRIEL RENE LOPEZ GAXIOLA | G12: IRLANDA FRANCIS GARCIA GAMEZ | H12: MARIA FERNANDA LOPEZ GAMEZ | I12: RUY RENDON LEAL | J12: GERARDO CAMACHO PONCE | K12: 3 | L12: 12 | M12: 23
A13: 7 | B13: JOSE ARMANDO ESPINOZA QUEZADA | C13: 21 | D13: JUNIO | E13: 2023 | F13: JOEL ARMANDO ESPINOZA FLORES | G13: ASTRID SELENE QUEZADA ENCINAS | H13: JOSE JAIME QUEZADA ARROYO | I13: RUY RENDON LEAL | J13: GERARDO CAMACHO PONCE | K13: 3 | L13: 12 | M13: 24
A14: 8 | B14: JOSE EDUARDO LOPEZ BADILLA | C14: 21 | D14: JUNIO | E14: 2023 | F14: MANUEL DE JESUS LOPEZ ONTIVEROS | G14: MARIA LUISA BADILLA MALDONADO | H14: JOSE PABLO MARQUEZ BUSTAMANTE | I14: RUY RENDON LEAL | J14: GERARDO CAMACHO PONCE | K14: 3 | L14: 13 | M14: 25
A15: 9 | B15: JUAN MANUEL BETANCOURT JR. | C15: 21 | D15: JUNIO | E15: 2023 | F15: JUAN MANUEL BETANCOURT RODRIGUEZ | G15: SUJEY ROJAS SILVA | H15: MARIA GUADALUPE SILVA PLAZA | I15: RUY RENDON LEAL | J15: GERARDO CAMACHO PONCE | K15: 3 | L15: 13 | M15: 26
A16: 10 | B16: KAROL JANETH MADRID HUERTA | C16: 21 | D16: JUNIO | E16: 2023 | F16: MANUEL JUVENTINO MADRID GARCIA | G16: IRMA JEANNETTE HUERTA ROMO | H16: RAFAELA BERENICE MADRID GARCIA | I16: RUY RENDON LEAL | J16: GERARDO CAMACHO PONCE | K16: 3 | L16: 14 | M16: 27
A17: 11 | B17: LUIS EMILIO RUIZ CORTEZ | C17: 21 | D17: JUNIO | E17: 2023 | F17: LUIS ALBERTO RUIZ CORONADO | G17: AIDA REFUGIO CORTEZ DURAN | H17: MARIO ALBERTO RUIZ CORTEZ | I17: RUY RENDON LEAL | J17: GERARDO CAMACHO PONCE | K17: 3 | L17: 14 | M17: 28
A18: 12 | B18: NOEL ALEJANDRO SANCHEZ PAEZ | C18: 21 | D18: JUNIO | E18: 2023 | F18: NOEL ALEJANDRO SANCHEZ ESTRADA | G18: AMINA GEORGETTE PAEZ | H18: JORGE ARTURO ESTRADA | I18: RUY RENDON LEAL | J18: GERARDO CAMACHO PONCE | K18: 3 | L18: 15 | M18: 29
... A22: 16 | B22: XIMENA RODRIGUEZ ROSAS | C22: 21 | D22: JUNIO | E22: 2023 | F22: LUIS GONZAGA RODRIGUEZ MORENO | G22: ERIKA JANETH ROSAS ENCISO | H22: ARNOLD IVANISSE GOMEZ CRUZ | I22: RUY RENDON LEAL | J22: GERARDO CAMACHO PONCE | K22: 3 | L22: 17 | M22: 33
B25: NTRA SRA DE LA PAZ - MAIRA AURORA
B26: NIÑA O NIÑO | C26: DIA | D26: MES | E26: AÑO | F26: PAPA | G26: MAMA | H26: MADRINA O PADRINO | I26: ARZOBISPO | J26: PARROCO | K26: LIBRO | L26: PAGINA | M26: PARTIDA
A27: 17 | B27: ANA SOFIA GAMEZ BOJORQUEZ | C27: 21 | D27: JUNIO | E27: 2023 | F27: JESUS ARMANDO GAMEZ CELAYA | G27: DULCE MARIA BOJORQUEZ CHAVEZ | H27: MIRIAM GUADALUPE BOJORQUEZ CHAVEZ | I27: RUY RENDON LEAL | J27: GERARDO CAMACHO PONCE | K27: 3 | L27: 17 | M27: 34
A28: 18 | B28: ANETTE ANDALON INZUNZA | C28: 21 | D28: JUNIO | E28: 2023 | F28: JORGE LUIS ANDALON MARTINEZ | G28: FLORIZEL INZUNZA TISNADO | H28: LILIANA ANDALON MARTINEZ | I28: RUY RENDON LEAL | J28: GERARDO CAMACHO PONCE | K28: 3 | L28: 18 | M28: 35
A29: 19 | B29: AXEL ALEJANDRO DE ESESARTE BOJORQUEZ | C29: 21 | D29: JUNIO | E29: 2023 | F29: ALEJANDRO DE ESESARTE NAVARRO | G29: KARLA MARIELA BOJORQUEZ LOPEZ | H29: CLAUDIA TRUJILLO LEYVA | I29: RUY RENDON LEAL | J29: GERARDO CAMACHO PONCE | K29: 3 | L29: 18 | M29: 36
A30: 20 | B30: CARLOS ALEJANDRO SANDOVAL MARTINEZ | C30: 21 | D30: JUNIO | E30: 2023 | F30: CARLOS MANUEL SANDOVAL VILLA | G30: MARIBEL MARTINEZ LEON | H30: LUCIA GUADALUPE MARES GUTIERREZ Y JESUS ERNESTO COTA MONTAÑO | I30: RUY RENDON LEAL | J30: GERARDO CAMACHO PONCE | K30: 3 | L30: 19 | M30: 37
A31: 21 | B31: DANNA VALERIA CORDOVA ROCHA | C31: 21 | D31: JUNIO | E31: 2023 | F31: JUAN ANTONIO CORDOVA FELIX | G31: ALMA TERESITA ROCHA QUINTANAR | H31: JUDITH LORENIA CORDOVA FELIX | I31: RUY RENDON LEAL | J31: GERARDO CAMACHO PONCE | K31: 3 | L31: 19 | M31: 38
A32: 22 | B32: ESTEBAN ROMANDIA ESCOBAR | C32: 21 | D32: JUNIO | E32: 2023 | F32: JULIAN ESTEBAN ROMANDIA PADILLA | G32: CRISTINA MARGARITA ESCOBAR MADRID | H32: JULIAN ESTEBAN ROMANDIA PADILLA Y CRISTINA MARGARITA ESCOBAR MADRID | I32: RUY RENDON LEAL | J32: GERARDO CAMACHO PONCE | K32: 3 | L32: 20 | M32: 39
A33: 23 | B33: IVAN ALEXYS IBARRA LUNA | C33: 21 | D33: JUNIO | E33: 2023 | F33: IVAN ELLIOT IBARRA ORTEGA | G33: BERENICE LUNA HERNANDEZ | H33: RAMON ALAN IBARRA ORTEGA | I33: RUY RENDON LEAL | J33: GERARDO CAMACHO PONCE | K33: 3 | L33: 20 | M33: 40
A34: 24 | B34: JOSE ALEJANDRO HURTADO RODRIGUEZ | C34: 21 | D34: JUNIO | E34: 2023 | F34: FRANCISCO JAVIER HURTADO LEY | G34: DOLORES RODRIGUEZ MUÑOZ | H34: JOSE MANUEL ALVAREZ FLORES | I34: RUY RENDON LEAL | J34: GERARDO CAMACHO PONCE | K34: 3 | L34: 21 | M34: 41
A35: 25 | B35: JOSE FRANCISCO BUELNA GODOY | C35: 21 | D35: JUNIO | E35: 2023 | F35: FRANCISCO BUELNA ACOSTA | G35: JESSICA GODOY CERVANTES | H35: JESUS ANTONIO ACOSTA MURILLO | I35: RUY RENDON LEAL | J35: GERARDO CAMACHO PONCE | K35: 3 | L35: 21 | M35: 42
A36: 26 | B36: KASSANDRA MURILLO MONTAÑO | C36: 21 | D36: JUNIO | E36: 2023 | F36: HERIBERTO MURILLO MARTINEZ | G36: KARLA PATRICIA MONTAÑO FIGUEROA | H36: CRISTINA MURILLO MARTINEZ | I36: RUY RENDON LEAL | J36: GERARDO CAMACHO PONCE | K36: 3 | L36: 22 | M36: 43
A37: 27 | B37: LOAN JAVIER ACOSTA VEGA | C37: 21 | D37: JUNIO | E37: 2023 | F37: FRANCISCO JAVIER ACOSTA MEJIA | G37: ABIGAHIL VEGA GUERRERO | H37: MANUEL DE JASUS MONTAÑO IBARRA | I37: RUY RENDON LEAL | J37: GERARDO CAMACHO PONCE | K37: 3 | L37: 22 | M37: 44
A38: 28 | B38: MARIAN LOPEZ ROSAS | C38: 21 | D38: JUNIO | E38: 2023 | F38: HUMBERTO LOPEZ ESQUIVEL | G38: VERONICA ROSAS SIERRA | H38: LUIS ALFONSO ROSAS SIERRA | I38: RUY RENDON LEAL | J38: GERARDO CAMACHO PONCE | K38: 3 | L38: 23 | M38: 45
... A41: 31 | B41: SANDRO MIGUEL JIMENEZ MORENO | C41: 21 | D41: JUNIO | E41: 2023 | F41: ROBERTO BENITO JIMENEZ CRUZ | G41: VERONICA LIBRADA MORENO ESCAMILLA | H41: ANA LUCIA DAVILA ZAVALA | I41: RUY RENDON LEAL | J41: GERARDO CAMACHO PONCE | K41: 3 | L41: 24 | M41: 48
B43: NTRA SRA DE LA PAZ - SAMUEL
B44: NIÑA O NIÑO | C44: DIA | D44: MES | E44: AÑO | F44: PAPA | G44: MAMA | H44: MADRINA O PADRINO | I44: ARZOBISPO | J44: PARROCO | K44: LIBRO | L44: PAGINA | M44: PARTIDA
A45: 32 | B45: ABIGAIL HERNANDEZ GASTELUM | C45: 21 | D45: JUNIO | E45: 2023 | F45: JHOVANY HERNANDEZ VERDUGO | G45: ANA ALICIA GASTELUM CONTRERAS | H45: CONSEPCION FELIX RIVERA | I45: RUY RENDON LEAL | J45: GERARDO CAMACHO PONCE | K45: 3 | L45: 25 | M45: 49
A46: 33 | B46: ANA VALERIA ACOSTA FRAGOSO | C46: 21 | D46: JUNIO | E46: 2023 | F46: RAUL HORACIO ACOSTA FELIX | G46: ANA LAURA FRAGOSO CARRILLO | H46: ISADORA FRAGOSO CARRILLO | I46: RUY RENDON LEAL | J46: GERARDO CAMACHO PONCE | K46: 3 | L46: 25 | M46: 50
A47: 34 | B47: CAMILA MENESES NEVAREZ | C47: 21 | D47: JUNIO | E47: 2023 | F47: RAFAEL MENESES OCEJO | G47: JULIETA NEVAREZ LLAMAS | H47: ERIKA DENISSE NEVAREZ LLAMAS | I47: RUY RENDON LEAL | J47: GERARDO CAMACHO PONCE | K47: 3 | L47: 26 | M47: 51
A48: 35 | B48: CARLOS IVAN MADRID AVITIA | C48: 21 | D48: JUNIO | E48: 2023 | F48: ERNESTO MADRID SALAZAR | G48: ROSA MARIA AVITIA NUÑEZ | H48: VERONICA SALAZAR DURAZO | I48: RUY RENDON LEAL | J48: GERARDO CAMACHO PONCE | K48: 3 | L48: 26 | M48: 52
A49: 36 | B49: DANNA OLMEDO RODRIGUEZ | C49: 21 | D49: JUNIO | E49: 2023 | F49: ABEL ANTONIO OLMEDO RUELAS | G49: ANALCIRA RODRIGUEZ FIGUEROA | H49: ANA LILIAN ALVAREZ LOPEZ | I49: RUY RENDON LEAL | J49: GERARDO CAMACHO PONCE | K49: 3 | L49: 27 | M49: 53
A50: 37 | B50: DEMIAN VILLAVICENCIO MOLINA | C50: 21 | D50: JUNIO | E50: 2023 | F50: SAUL VILLAVICENCIO GONZALEZ | G50: LORENA MOLINA YANEZ | H50: JESUS ENRIQUE AGUIRRE FELIX | I50: RUY RENDON LEAL | J50: GERARDO CAMACHO PONCE | K50: 3 | L50: 27 | M50: 54
...

Sheet IMPRESION-CONFIRMACION
A1: 331
D5: =LOOKUP($A$1,CONFIRMACION!$A$7:B1055) -> ABRIL RODARTE SANCHEZ
E8: =IF(LOOKUP($A$1,CONFIRMACION!$A$7:F1055)=0," ",LOOKUP($A$1,CONFIRMACION!$A$7:F1055)) -> JESUS FERNANDO RODARTE MORALES | I8: =LOOKUP($A$1,CONFIRMACION!$A$7:G1055) -> ANA CECILIA SANCHEZ YAÑEZ
C12: ARZ. RUY RENDÓN LEAL | H12: =IF(LOOKUP($A$1,CONFIRMACION!$A$7:C1059)=0," ",LOOKUP($A$1,CONFIRMACION!$A$7:C1059)) -> 15 | I12: =IF(LOOKUP($A$1,CONFIRMACION!$A$7:D1059)=0," ",LOOKUP($A$1,CONFIRMACION!$A$7:D1059)) -> JUNIO | J12: =IF(LOOKUP($A$1,CONFIRMACION!$A$7:E1059)=0," ",LOOKUP($A$1,CONFIRMACION!$A$7:E1059)) -> 2026
F14: =LOOKUP($A$1,CONFIRMACION!$A$7:H1055) -> GUADALUPE AMANDA CORONADO COLORES
F15: =LOOKUP($A$1,CONFIRMACION!$A$7:K1055) -> 3
F16: =LOOKUP($A$1,CONFIRMACION!$A$7:L1055) -> 174 | I16: =IF(LOOKUP($A$1,CONFIRMACION!A$7:$J1050)=0," ",LOOKUP($A$1,CONFIRMACION!A$7:$J1050)) -> GERARDO CAMACHO PONCE
F17: =LOOKUP($A$1,CONFIRMACION!$A$7:M1055) -> 348

Sheet BAUTIZMO
B3: CONSTANCIA DE BAUTISMO
D5: FECHA NACIMIENTO | G5: LUGAR | J5: FECHA BAUTISMO
B6: NIÑA O NIÑO | D6: DIA | E6: MES | F6: AÑO | G6: DE NACIMIENTO | H6: PAPA | I6: MAMA | J6: DIA | K6: MES | L6: AÑO | M6: MINISTRO | N6: PADRINO | O6: MADRINA | P6: PÁRROCO | Q6: REGISTRO NO. | U6: Libro | V6: Pagina | W6: Acta
B7: BAUTIZOS DEL 2023
A8: 1 | B8: FERNANDO VAZQUEZ SALVADOR | D8: 3 | E8: ABRIL | F8: 2022 | G8: HERMOSILLO, SONORA | H8: FERNANDO VAZQUEZ GAMEZ | I8: ALEJANDRA SALVADOR ZAMORANO | J8: 14 | K8: ENERO | L8: 2023 | M8: PBRO. GERARDO CAMACHO PONCE | N8: EFREN ARISTEO MENDIVIL VALENCIA | O8: MARIA VICTORIA SALVADOR ZAMORANO | P8: GERARDO CAMACHO PONCE | Q8: 806 | R8: =H8&" Y "&I8 -> FERNANDO VAZQUEZ GAMEZ Y ALEJANDRA SALVADOR ZAMORANO | S8: =D8&" "&E8&" DE "&F8 -> 3 ABRIL DE 2022 | T8: =J8&" "&K8&" DE "&L8 -> 14 ENERO DE 2023 | U8: 2 | V8: 198 | W8: 396
A9: 2 | B9: EDUARDO ESCALANTE BRUNET | D9: 19 | E9: FEBRERO | F9: 2022 | G9: HERMOSILLO, SONORA | H9: JESUS EDUARDO ESCALANTE ROSALES | I9: ALEJANDRA DALI BRUNET FIGUEROA | J9: 18 | K9: FEBRERO | L9: 2023 | M9: PBRO. GERARDO CAMACHO PONCE | N9: NOE ALBERTO CUAMEA PIÑA | O9: MARITZA MARTINEZ MUNGIA | P9: GERARDO CAMACHO PONCE | Q9: 434 | R9: =H9&" Y "&I9 -> JESUS EDUARDO ESCALANTE ROSALES Y ALEJANDRA DALI BRUNET FIGUEROA | S9: =D9&" "&E9&" DE "&F9 -> 19 FEBRERO DE 2022 | T9: =J9&" "&K9&" DE "&L9 -> 18 FEBRERO DE 2023 | U9: 2 | V9: 199 | W9: 397
A10: 3 | B10: YADIRA ALEJANDRA GUZMAN CASAS | D10: 21 | E10: FEBRERO | F10: 2022 | G10: HERMOSILLO, SONORA | H10: MARTIN ALEJANDRO GUZMAN DURON | I10: CINTHYA YANETH CASAS CORRALES | J10: 4 | K10: MARZO | L10: 2023 | M10: PBRO. GERARDO CAMACHO PONCE | N10: CARLOS ERNESTO GUZMAN DURON | O10: ILLIANA MARIA MARCOFF BRAVO | P10: GERARDO CAMACHO PONCE | Q10: 762 | R10: =H10&" Y "&I10 -> MARTIN ALEJANDRO GUZMAN DURON Y CINTHYA YANETH CASAS CORRALES | S10: =D10&" "&E10&" DE "&F10 -> 21 FEBRERO DE 2022 | T10: =J10&" "&K10&" DE "&L10 -> 4 MARZO DE 2023 | U10: 2 | V10: 199 | W10: 398
A11: 4 | B11: ANDREA ORTIZ ALVAREZ | D11: 9 | E11: MARZO | F11: 2022 | G11: HERMOSILLO, SONORA | H11: OSCAR ALEJANDRO ORTIZ CAMPOS | I11: DIANA ALEXIS ALVAREZ BELTRAN | J11: 4 | K11: MARZO | L11: 2023 | M11: PBRO. GERARDO CAMACHO PONCE | N11: OSCAR ROBERTO BELTRAN GASTELUM | O11: CARMEN ROSARIO BELTRAN RENDON | P11: GERARDO CAMACHO PONCE | Q11: 1024 | R11: =H11&" Y "&I11 -> OSCAR ALEJANDRO ORTIZ CAMPOS Y DIANA ALEXIS ALVAREZ BELTRAN | S11: =D11&" "&E11&" DE "&F11 -> 9 MARZO DE 2022 | T11: =J11&" "&K11&" DE "&L11 -> 4 MARZO DE 2023 | U11: 2 | V11: 200 | W11: 399
A12: 5 | B12: EYDAN JAFET DELGADO ENCINAS | D12: 1 | E12: ABRIL | F12: 2022 | G12: HERMOSILLO, SONORA | H12: ANGEL JAFET DELGADO CHAVEZ | I12: ROCIO ESMERALDA ENCINAS BRACAMONTES | J12: 12 | K12: MARZO | L12: 2023 | M12: PBRO. GERARDO CAMACHO PONCE | N12: CRHISTIAN BECKER DELGADO CHAVEZ | O12: LUISA DAVINA RIOS ZAVALA | P12: GERARDO CAMACHO PONCE | Q12: 2099 | R12: =H12&" Y "&I12 -> ANGEL JAFET DELGADO CHAVEZ Y ROCIO ESMERALDA ENCINAS BRACAMONTES | S12: =D12&" "&E12&" DE "&F12 -> 1 ABRIL DE 2022 | T12: =J12&" "&K12&" DE "&L12 -> 12 MARZO DE 2023 | U12: 2 | V12: 200 | W12: 400
A13: 6 | B13: SANTIAGO NAVA ESQUER | D13: 28 | E13: FEBRERO | F13: 2020 | G13: HERMOSILLO, SONORA | H13: FERNANDO NAVA GUEVARA | I13: MARISOL ESQUER CASTRO | J13: 18 | K13: MARZO | L13: 2023 | M13: PBRO. GERARDO CAMACHO PONCE | N13: LUIS ARMANDO VALENCIA FIGUEROA | O13: ALONDRA ESQUER GANDARILLA | P13: GERARDO CAMACHO PONCE | Q13: 766 | R13: =H13&" Y "&I13 -> FERNANDO NAVA GUEVARA Y MARISOL ESQUER CASTRO | S13: =D13&" "&E13&" DE "&F13 -> 28 FEBRERO DE 2020 | T13: =J13&" "&K13&" DE "&L13 -> 18 MARZO DE 2023 | U13: 2 | V13: 201 | W13: 401
A14: 7 | B14: EMILIO LOPEZ ALMADA | D14: 10 | E14: MARZO | F14: 2022 | G14: HERMOSILLO, SONORA | H14: EDGARDO LOPEZ ANGUIS | I14: ESTEFANIA GUADALUPE ALMADA FUENTES | J14: 18 | K14: MARZO | L14: 2023 | M14: PBRO. GERARDO CAMACHO PONCE | N14: ALAN FRANCISCO GUTIERREZ CAMPOY | O14: ESTHELA MARIA AVILA ANGUIS | P14: GERARDO CAMACHO PONCE | Q14: 457 | R14: =H14&" Y "&I14 -> EDGARDO LOPEZ ANGUIS Y ESTEFANIA GUADALUPE ALMADA FUENTES | S14: =D14&" "&E14&" DE "&F14 -> 10 MARZO DE 2022 | T14: =J14&" "&K14&" DE "&L14 -> 18 MARZO DE 2023 | U14: 2 | V14: 201 | W14: 402
A15: 8 | B15: AMELIA LUCIA ROMERO PEREZ | D15: 28 | E15: OCTUBRE | F15: 2021 | G15: HERMOSILLO, SONORA | H15: JORGE ANDRES ROMERO ANDRADE | I15: MARTHA SELENE PEREZ OROZCO | J15: 18 | K15: MARZO | L15: 2023 | M15: PBRO. GERARDO CAMACHO PONCE | N15: JAIME ALBERTO RENTERIA BECERRA | O15: PAULA CRISTINA ROMERO ANDRADE | P15: GERARDO CAMACHO PONCE | Q15: 1764 | R15: =H15&" Y "&I15 -> JORGE ANDRES ROMERO ANDRADE Y MARTHA SELENE PEREZ OROZCO | S15: =D15&" "&E15&" DE "&F15 -> 28 OCTUBRE DE 2021 | T15: =J15&" "&K15&" DE "&L15 -> 18 MARZO DE 2023 | U15: 2 | V15: 202 | W15: 403
A16: 9 | B16: REGINA GUADALUPE ARAIZA REYNA | D16: 21 | E16: ABRIL | F16: 2019 | G16: TUCSON, ARIZONA | H16: JESUS MIGUEL ARAIZA CARRILLO | I16: NEREYDA ALEXANDRA REYNA HERNANDEZ | J16: 19 | K16: MARZO | L16: 2023 | M16: PBRO. GERARDO CAMACHO PONCE | N16: JESUS ARAIZA MARQUEZ | O16: ERICKA VALENZUELA BELTRAN | P16: GERARDO CAMACHO PONCE | Q16: 23727 | R16: =H16&" Y "&I16 -> JESUS MIGUEL ARAIZA CARRILLO Y NEREYDA ALEXANDRA REYNA HERNANDEZ | S16: =D16&" "&E16&" DE "&F16 -> 21 ABRIL DE 2019 | T16: =J16&" "&K16&" DE "&L16 -> 19 MARZO DE 2023 | U16: 2 | V16: 202 | W16: 404
A17: 10 | B17: RENATA SARAHI ARAIZA REYNA | D17: 10 | E17: ENERO | F17: 2021 | G17: TUCSON, ARIZONA | H17: JESUS MIGUEL ARAIZA CARRILLO | I17: NEREYDA ALEXANDRA REYNA HERNANDEZ | J17: 19 | K17: MARZO | L17: 2023 | M17: PBRO. GERARDO CAMACHO PONCE | N17: ENRIQUE GUZMAN | O17: VERONICA HERNANDEZ LOPEZ | P17: GERARDO CAMACHO PONCE | Q17: 57495 | R17: =H17&" Y "&I17 -> JESUS MIGUEL ARAIZA CARRILLO Y NEREYDA ALEXANDRA REYNA HERNANDEZ | S17: =D17&" "&E17&" DE "&F17 -> 10 ENERO DE 2021 | T17: =J17&" "&K17&" DE "&L17 -> 19 MARZO DE 2023 | U17: 2 | V17: 203 | W17: 405
A18: 11 | B18: GIAN ALBERTO SEGURA CAMARGO | D18: 31 | E18: DICIEMBRE | F18: 2021 | G18: HERMOSILLO, SONORA | H18: JESUS YOBANI SEGURA GARCIA | I18: ADILENE FRANCISCA CAMARGO CASTELO | J18: 19 | K18: MARZO | L18: 2023 | M18: PBRO. GERARDO CAMACHO PONCE | N18: DANIEL EDUARDO MEDRANO GARCIA | O18: NATALIA ELIZABETH MEDINA JIMENEZ | P18: GERARDO CAMACHO PONCE | Q18: 597 | R18: =H18&" Y "&I18 -> JESUS YOBANI SEGURA GARCIA Y ADILENE FRANCISCA CAMARGO CASTELO | S18: =D18&" "&E18&" DE "&F18 -> 31 DICIEMBRE DE 2021 | T18: =J18&" "&K18&" DE "&L18 -> 19 MARZO DE 2023 | U18: 2 | V18: 203 | W18: 406
A19: 12 | B19: REBECCA MURILLO ROBLES | D19: 10 | E19: AGOSTO | F19: 2022 | G19: HERMOSILLO, SONORA | H19: JOHNATAN MURILLO VELARDE | I19: CRISTINA GUADALUPE ROBLES MOROYOQUI | J19: 26 | K19: MARZO | L19: 2023 | M19: PBRO. GERARDO CAMACHO PONCE | N19: ADOLFO ALBERTO MURILLO VELARDE | O19: PAMELA ALEJANDRA VEGA IRRA | P19: GERARDO CAMACHO PONCE | Q19: 3443 | R19: =H19&" Y "&I19 -> JOHNATAN MURILLO VELARDE Y CRISTINA GUADALUPE ROBLES MOROYOQUI | S19: =D19&" "&E19&" DE "&F19 -> 10 AGOSTO DE 2022 | T19: =J19&" "&K19&" DE "&L19 -> 26 MARZO DE 2023 | U19: 2 | V19: 204 | W19: 407
A20: 13 | B20: MATEO FERNANDO ORTEZ RODRIGUEZ | D20: 6 | E20: MAYO | F20: 2013 | G20: GUAYMAS SONORA | H20: MANUEL RODRIGUEZ LOPEZ | I20: MARIA FERNANDA ORTEZ RODRIGUEZ | J20: 26 | K20: MARZO | L20: 2023 | M20: PBRO. GERARDO CAMACHO PONCE | N20: EDUARDO GONZALEZ ORTEZ | P20: GERARDO CAMACHO PONCE | Q20: 928 | R20: =H20&" Y "&I20 -> MANUEL RODRIGUEZ LOPEZ Y MARIA FERNANDA ORTEZ RODRIGUEZ | S20: =D20&" "&E20&" DE "&F20 -> 6 MAYO DE 2013 | T20: =J20&" "&K20&" DE "&L20 -> 26 MARZO DE 2023 | U20: 2 | V20: 204 | W20: 408
A21: 14 | B21: MARCIA PATRICIA CARRION ZEPEDA | D21: 28 | E21: JULIO | F21: 2022 | G21: HERMOSILLO, SONORA | H21: CARLOS ALBERTO CARRION TRACONIS | I21: MARCIA IVONE ZEPEDA PERALTA | J21: 26 | K21: MARZO | L21: 2023 | M21: PBRO. GERARDO CAMACHO PONCE | N21: JESUS GUILLERMO CORONADO MUÑOZ | O21: MARCIA ROSELA MUNGUIA HERRERA | P21: GERARDO CAMACHO PONCE | Q21: 1268 | R21: =H21&" Y "&I21 -> CARLOS ALBERTO CARRION TRACONIS Y MARCIA IVONE ZEPEDA PERALTA | S21: =D21&" "&E21&" DE "&F21 -> 28 JULIO DE 2022 | T21: =J21&" "&K21&" DE "&L21 -> 26 MARZO DE 2023 | U21: 2 | V21: 205 | W21: 409
A22: 15 | B22: VALERIA ELVIRA GARCIA NORIEGA | D22: 24 | E22: JULIO | F22: 2005 | G22: HERMOSILLO, SONORA | H22: JAVIER GARCIA CASTRO | I22: CLAUDIA NORIEGA BARRERA | J22: 29 | K22: MARZO | L22: 2023 | M22: PBRO. GERARDO CAMACHO PONCE | N22: JOEL SANTIAGO RIVERA NEVAREZ | O22: YESSENIA PATRICIA NORIEGA BARRERA | P22: GERARDO CAMACHO PONCE | Q22: 474 | R22: =H22&" Y "&I22 -> JAVIER GARCIA CASTRO Y CLAUDIA NORIEGA BARRERA | S22: =D22&" "&E22&" DE "&F22 -> 24 JULIO DE 2005 | T22: =J22&" "&K22&" DE "&L22 -> 29 MARZO DE 2023 | U22: 2 | V22: 205 | W22: 410
A23: 16 | B23: DENISSE SOFIA GARCIA LOPEZ | D23: 18 | E23: DICIEMBRE | F23: 2013 | G23: HERMOSILLO, SONORA | H23: ALVARO OSWALDO GARCIA ARIAS | J23: 1 | K23: ABRIL | L23: 2023 | M23: PBRO. GERARDO CAMACHO PONCE | N23: JUAN SALVADOR MARTINEZ TALAMANTES | O23: CYNTHIA ELIZABETH VERJAN ESQUER | P23: GERARDO CAMACHO PONCE | Q23: 1238 | R23: =H23&" Y "&I23 -> ALVARO OSWALDO GARCIA ARIAS Y | S23: =D23&" "&E23&" DE "&F23 -> 18 DICIEMBRE DE 2013 | T23: =J23&" "&K23&" DE "&L23 -> 1 ABRIL DE 2023 | U23: 2 | V23: 206 | W23: 411
A24: 17 | B24: ROQUE ISMAEL MOLINA ORTIZ | D24: 26 | E24: FEBRERO | F24: 2022 | G24: HERMOSILLO, SONORA | H24: AURELIANO MOLINA DANIEL | I24: ELIZABETH ORTIZ VALENCIA | J24: 1 | K24: ABRIL | L24: 2023 | M24: PBRO. GERARDO CAMACHO PONCE | N24: JOSE LUIS LIMON BASACA | O24: ALMA LORENA LOPEZ PEREZ | P24: GERARDO CAMACHO PONCE | Q24: 1303 | R24: =H24&" Y "&I24 -> AURELIANO MOLINA DANIEL Y ELIZABETH ORTIZ VALENCIA | S24: =D24&" "&E24&" DE "&F24 -> 26 FEBRERO DE 2022 | T24: =J24&" "&K24&" DE "&L24 -> 1 ABRIL DE 2023 | U24: 2 | V24: 206 | W24: 412
A25: 18 | B25: GABRIEL ALFONSO PATRON GALVEZ | D25: 3 | E25: NOVIEMBRE | F25: 2022 | G25: HERMOSILLO, SONORA | H25: MIGUEL ALFONSO PATRON AVILES | I25: KAREN VIANNEY GALVEZ GARCIA | J25: 16 | K25: ABRIL | L25: 2023 | M25: PBRO. GERARDO CAMACHO PONCE | N25: LUIS ARMANDO CONTRERAS AGUAYO | O25: ANA GABRIELA FONTES GARCIA | P25: GERARDO CAMACHO PONCE | Q25: 2385 | R25: =H25&" Y "&I25 -> MIGUEL ALFONSO PATRON AVILES Y KAREN VIANNEY GALVEZ GARCIA | S25: =D25&" "&E25&" DE "&F25 -> 3 NOVIEMBRE DE 2022 | T25: =J25&" "&K25&" DE "&L25 -> 16 ABRIL DE 2023 | U25: 2 | V25: 207 | W25: 413
A26: 19 | B26: MYA ISABELA PATRON GALVEZ | D26: 29 | E26: NOVIEMBRE | F26: 2021 | G26: HERMOSILLO, SONORA | H26: MIGUEL ALFONSO PATRON AVILES | I26: KAREN VIANNEY GALVEZ GARCIA | J26: 16 | K26: ABRIL | L26: 2023 | M26: PBRO. GERARDO CAMACHO PONCE | N26: LUIS ARMANDO CONTRERAS AGUAYO | O26: ANA GABRIELA FONTES GARCIA | P26: GERARDO CAMACHO PONCE | Q26: 1822 | R26: =H26&" Y "&I26 -> MIGUEL ALFONSO PATRON AVILES Y KAREN VIANNEY GALVEZ GARCIA | S26: =D26&" "&E26&" DE "&F26 -> 29 NOVIEMBRE DE 2021 | T26: =J26&" "&K26&" DE "&L26 -> 16 ABRIL DE 2023 | U26: 2 | V26: 207 | W26: 414
A27: 20 | B27: MARISSA RASCON CARVAJAL | D27: 6 | E27: DICIEMBRE | F27: 2022 | G27: HERMOSILLO, SONORA | H27: JESUS TADEO RASCON ANDRADE | I27: ANA ISABEL CARvAJAL ACUÑA | J27: 23 | K27: ABRIL | L27: 2023 | M27: PBRO. GERARDO CAMACHO PONCE | N27: LUIS ALAN SANTINI COHIRA Y RITA MARIA NORIEGA NOYOLA | O27: ALBERTO TERAN ROMERO | P27: GERARDO CAMACHO PONCE | Q27: 158 | R27: =H27&" Y "&I27 -> JESUS TADEO RASCON ANDRADE Y ANA ISABEL CARvAJAL ACUÑA | S27: =D27&" "&E27&" DE "&F27 -> 6 DICIEMBRE DE 2022 | T27: =J27&" "&K27&" DE "&L27 -> 23 ABRIL DE 2023 | U27: 2 | V27: 208 | W27: 415
A28: 21 | B28: ANGELIQUE PAOLET AGUILAR ORTIZ | D28: 10 | E28: JUNIO | F28: 2011 | G28: HERMOSILLO, SONORA | H28: GUSTAVO AGUILAR SANTACRUZ | I28: GLADYS JANETH ORTIZ LEON | J28: 11 | K28: MAYO | L28: 2023 | M28: PBRO. GERARDO CAMACHO PONCE | N28: JULIO CESAR ARRIQUIVEZ ESQUER | O28: JOANA GUADALUPE ORTIZ LEON | P28: GERARDO CAMACHO PONCE | Q28: 3177 | R28: =H28&" Y "&I28 -> GUSTAVO AGUILAR SANTACRUZ Y GLADYS JANETH ORTIZ LEON | S28: =D28&" "&E28&" DE "&F28 -> 10 JUNIO DE 2011 | T28: =J28&" "&K28&" DE "&L28 -> 11 MAYO DE 2023 | U28: 2 | V28: 208 | W28: 416
A29: 22 | B29: OSCAR ALAN BARRETO VALENZUELA | D29: 16 | E29: AGOSTO | F29: 2022 | G29: HERMOSILLO, SONORA | H29: OSCAR ALAN BARRETO RIOS | I29: ROSA STEPHANIE VALENZUELA FLORES | J29: 21 | K29: MAYO | L29: 2023 | M29: PBRO. GERARDO CAMACHO PONCE | N29: MARCO ANTONIO BARRETO RIOS | O29: GUADALUPE CORONADO GOMEZ | P29: GERARDO CAMACHO PONCE | Q29: 2560 | R29: =H29&" Y "&I29 -> OSCAR ALAN BARRETO RIOS Y ROSA STEPHANIE VALENZUELA FLORES | S29: =D29&" "&E29&" DE "&F29 -> 16 AGOSTO DE 2022 | T29: =J29&" "&K29&" DE "&L29 -> 21 MAYO DE 2023 | U29: 2 | V29: 209 | W29: 417
A30: 23 | B30: ANA LUISA ISLAS KITAZAWA | D30: 25 | E30: JULIO | F30: 2022 | G30: HERMOSILLO, SONORA | H30: LUIS NAPOLEON ISLAS IBARRA | I30: ANA DEL CARMEN KITAZAWA LEYVA | J30: 3 | K30: JUNIO | L30: 2023 | M30: PBRO. GERARDO CAMACHO PONCE | N30: JUAN EDUARDO KITAZAWA LEYVA | O30: EVANGELINA ISLAS IBARRA | P30: GERARDO CAMACHO PONCE | Q30: 2190 | R30: =H30&" Y "&I30 -> LUIS NAPOLEON ISLAS IBARRA Y ANA DEL CARMEN KITAZAWA LEYVA | S30: =D30&" "&E30&" DE "&F30 -> 25 JULIO DE 2022 | T30: =J30&" "&K30&" DE "&L30 -> 3 JUNIO DE 2023 | U30: 2 | V30: 209 | W30: 418
A31: 24 | B31: VARENA LUCIA DE LA CRUZ RESENDIZ | D31: 9 | E31: NOVIEMBRE | F31: 2022 | G31: HERMOSILLO, SONORA | H31: JESUS ENRIQUE DE LA CRUZ ENCINAS | I31: VICTORIA BERENICE RESENDIZ MACHO | J31: 3 | K31: JUNIO | L31: 2023 | M31: PBRO. GERARDO CAMACHO PONCE | N31: JULIO CESAR AVILA ROMERO | O31: MONICA TORRES ROMERO | P31: GERARDO CAMACHO PONCE | Q31: 3200 | R31: =H31&" Y "&I31 -> JESUS ENRIQUE DE LA CRUZ ENCINAS Y VICTORIA BERENICE RESENDIZ MACHO | S31: =D31&" "&E31&" DE "&F31 -> 9 NOVIEMBRE DE 2022 | T31: =J31&" "&K31&" DE "&L31 -> 3 JUNIO DE 2023 | U31: 2 | V31: 210 | W31: 419
A32: 25 | B32: MARIA CORELLA SALCIDO | D32: 7 | E32: ENERO | F32: 2023 | G32: HERMOSILLO, SONORA | H32: LUIS FELIPE CORELLA OROZCO | I32: REYNA GUADALUPE SALCIDO CORRALES | J32: 11 | K32: JUNIO | L32: 2023 | M32: PBRO. GERARDO CAMACHO PONCE | N32: HECTOR ARMANDO CASTRO ORTEGA | O32: LORENA SALCIDO CORRALES | P32: GERARDO CAMACHO PONCE | Q32: 335 | R32: =H32&" Y "&I32 -> LUIS FELIPE CORELLA OROZCO Y REYNA GUADALUPE SALCIDO CORRALES | S32: =D32&" "&E32&" DE "&F32 -> 7 ENERO DE 2023 | T32: =J32&" "&K32&" DE "&L32 -> 11 JUNIO DE 2023 | U32: 2 | V32: 210 | W32: 420
A33: 26 | B33: LEGNA MAYLIN CORRAL JIMENEZ | D33: 6 | E33: JUNIO | F33: 2022 | G33: HERMOSILLO, SONORA | H33: ANGEL DE JESUS CORRAL AGUILAR | I33: ZARET DE JESUS JIMENEZ TORRES | J33: 11 | K33: JUNIO | L33: 2023 | M33: PBRO. GERARDO CAMACHO PONCE | N33: HUMBERTO MARQUEZ RUIZ | O33: FRANCISCA CRISTINA DIAZ TORRES | P33: GERARDO CAMACHO PONCE | Q33: 1827 | R33: =H33&" Y "&I33 -> ANGEL DE JESUS CORRAL AGUILAR Y ZARET DE JESUS JIMENEZ TORRES | S33: =D33&" "&E33&" DE "&F33 -> 6 JUNIO DE 2022 | T33: =J33&" "&K33&" DE "&L33 -> 11 JUNIO DE 2023 | U33: 2 | V33: 211 | W33: 421
A34: 27 | B34: RENATA AYDEE RUBIO SOLIS | D34: 12 | E34: JUNIO | F34: 2017 | G34: HERMOSILLO, SONORA | H34: MARTIN ALBERTO RUBIO VALENZUELA | I34: DOLORES MARGARITA SOLIS FLORES | J34: 17 | K34: JUNIO | L34: 2023 | M34: PBRO. ANDRES GADALUPE SALAZAR ANGULO | N34: EDGAR DANIEL BANDA HERRERA | O34: EMMA CZARINA BRAVO LOPEZ | P34: GERARDO CAMACHO PONCE | Q34: 2476 | R34: =H34&" Y "&I34 -> MARTIN ALBERTO RUBIO VALENZUELA Y DOLORES MARGARITA SOLIS FLORES | S34: =D34&" "&E34&" DE "&F34 -> 12 JUNIO DE 2017 | T34: =J34&" "&K34&" DE "&L34 -> 17 JUNIO DE 2023 | U34: 2 | V34: 211 | W34: 422
A35: 28 | B35: HANSEL MATEO MARTINEZ MARTINEZ | D35: 30 | E35: JUNIO | F35: 2022 | G35: HERMOSILLO, SONORA | H35: HANSEL EFRAIN MARTINEZ LLAMAS | I35: MARIA ISABEL MARTINEZ VALENCIA | J35: 1 | K35: JULIO | L35: 2023 | M35: PBRO. GERARDO CAMACHO PONCE | N35: MANUEL ENRIQUE BUJANDA QUIJADA | O35: REYNA JULIETA FELIX ORTIZ | P35: GERARDO CAMACHO PONCE | Q35: 1141 | R35: =H35&" Y "&I35 -> HANSEL EFRAIN MARTINEZ LLAMAS Y MARIA ISABEL MARTINEZ VALENCIA | S35: =D35&" "&E35&" DE "&F35 -> 30 JUNIO DE 2022 | T35: =J35&" "&K35&" DE "&L35 -> 1 JULIO DE 2023 | U35: 2 | V35: 212 | W35: 423
... A57: 50 | B57: SANTIAGO IGNACIO VALENZUELA SALCIDO | D57: 18 | E57: DICIEMBRE | F57: 2022 | G57: HERMOSILLO, SONORA | H57: DAVID IGNACIO VALENZUELA DOMINGUEZ | I57: GABRIELA BELEM SALCIDO RUIZ | J57: 17 | K57: DICIEMBRE | L57: 2023 | M57: PBRO. GERARDO CAMACHO PONCE | N57: JUAN PABLO PRECIADO SALCIDO | O57: KARLA IVONNE SALCIDO RUIZ | P57: GERARDO CAMACHO PONCE | Q57: 329 | R57: =H57&" Y "&I57 -> DAVID IGNACIO VALENZUELA DOMINGUEZ Y GABRIELA BELEM SALCIDO RUIZ | S57: =D57&" "&E57&" DE "&F57 -> 18 DICIEMBRE DE 2022 | T57: =J57&" "&K57&" DE "&L57 -> 17 DICIEMBRE DE 2023 | U57: 2 | V57: 223 | W57: 445
B58: BAUTIZOS DEL 2024
A59: 51 | B59: ANA CECILIA PARTIDA CUELLAR | D59: 7 | E59: FEBRERO | F59: 2023 | G59: HERMOSILLO, SONORA | H59: JOSE ANGEL PARTIDA RANGEL | I59: ANDREA STEPHNEE CUELLAR SALAS | J59: 4 | K59: FEBRERO | L59: 2024 | M59: PBRO. GERARDO CAMACHO PONCE | N59: DIEGO DE JESUS CUELLAR SALAS | O59: ANA SARAHI PARTIDA RANGEL | P59: GERARDO CAMACHO PONCE | Q59: 549 | R59: =H59&" Y "&I59 -> JOSE ANGEL PARTIDA RANGEL Y ANDREA STEPHNEE CUELLAR SALAS | S59: =D59&" "&E59&" DE "&F59 -> 7 FEBRERO DE 2023 | T59: =J59&" "&K59&" DE "&L59 -> 4 FEBRERO DE 2024 | U59: 2 | V59: 223 | W59: 446
A60: 52 | B60: CARLOS DANIEL SANCHEZ GOMEZ | D60: 11 | E60: FEBRERO | F60: 2023 | G60: HERMOSILLO, SONORA | H60: DANIEL SANCHEZ DORAME | I60: ANA CRISTINA GOMEZ LIMA | J60: 11 | K60: FEBRERO | L60: 2024 | M60: PBRO. GERARDO CAMACHO PONCE | N60: MIGUEL ANGEL GOMEZ LIMA | O60: LUCIA GUADALUPE DORAME BUERAS | P60: GERARDO CAMACHO PONCE | Q60: 660 | R60: =H60&" Y "&I60 -> DANIEL SANCHEZ DORAME Y ANA CRISTINA GOMEZ LIMA | S60: =D60&" "&E60&" DE "&F60 -> 11 FEBRERO DE 2023 | T60: =J60&" "&K60&" DE "&L60 -> 11 FEBRERO DE 2024 | U60: 2 | V60: 224 | W60: 447
A61: 53 | B61: AMBAR RENEE BRINGAS CHAVEZ | D61: 20 | E61: SEPTIEMBRE | F61: 2023 | G61: HERMOSILLO, SONORA | H61: IVAN BRINGAS SILVESTRE | I61: GUADALUPE EDUWVIGES CHAVEZ MIRANDA | J61: 17 | K61: FEBRERO | L61: 2024 | M61: PBRO. GERARDO CAMACHO PONCE | N61: MARIO SILVESTRE LOPEZ | O61: AIDA ELENA VALENZUELA MENDIVIL | P61: GERARDO CAMACHO PONCE | Q61: 2312 | R61: =H61&" Y "&I61 -> IVAN BRINGAS SILVESTRE Y GUADALUPE EDUWVIGES CHAVEZ MIRANDA | S61: =D61&" "&E61&" DE "&F61 -> 20 SEPTIEMBRE DE 2023 | T61: =J61&" "&K61&" DE "&L61 -> 17 FEBRERO DE 2024 | U61: 2 | V61: 224 | W61: 448
A62: 54 | B62: MARCELO ALEJANDRO MARQUEZ ESCOBAR | D62: 24 | E62: JULIO | F62: 2023 | G62: HERMOSILLO, SONORA | H62: MARION ALBERTO MARQUEZ SUAREZ | I62: MARIA FERNANDA ESCOBAR MONGE | J62: 2 | K62: MARZO | L62: 2024 | M62: PBRO. GERARDO CAMACHO PONCE | N62: ALBERTO ESCOBAR MONGE | O62: GREICE JULIETA BASS OROPEZA | P62: GERARDO CAMACHO PONCE | Q62: 1715 | R62: =H62&" Y "&I62 -> MARION ALBERTO MARQUEZ SUAREZ Y MARIA FERNANDA ESCOBAR MONGE | S62: =D62&" "&E62&" DE "&F62 -> 24 JULIO DE 2023 | T62: =J62&" "&K62&" DE "&L62 -> 2 MARZO DE 2024 | U62: 2 | V62: 225 | W62: 449
A63: 55 | B63: BENJAMIN MATEO SANTACRUZ HERNANDEZ | D63: 30 | E63: ENERO | F63: 2021 | G63: HERMOSILLO, SONORA | H63: BENJAMIN SANTACRUZ HERRERA | I63: TANIA GUADALUPE HERNANDEZ MALAVIAR | J63: 16 | K63: MARZO | L63: 2024 | M63: PBRO. GERARDO CAMACHO PONCE | N63: RICARDO ALEJANDRO OSUNA BUSTAMANTE | O63: MIRIAM SUGGEY ARVIZU HERNANDEZ | P63: GERARDO CAMACHO PONCE | Q63: 1493 | R63: =H63&" Y "&I63 -> BENJAMIN SANTACRUZ HERRERA Y TANIA GUADALUPE HERNANDEZ MALAVIAR | S63: =D63&" "&E63&" DE "&F63 -> 30 ENERO DE 2021 | T63: =J63&" "&K63&" DE "&L63 -> 16 MARZO DE 2024 | U63: 2 | V63: 225 | W63: 450
A64: 56 | B64: VALENTIN MONREAL SOLORZANO | D64: 12 | E64: MARZO | F64: 2023 | G64: HERMOSILLO, SONORA | H64: RODOLFO MONREAL CIRLOS | I64: SILVIA GUADALUPE SOLORZANO MONGE | J64: 16 | K64: MARZO | L64: 2024 | M64: PBRO. GERARDO CAMACHO PONCE | N64: MARIA DEL CARMEN MIRANDA VERDUGO | P64: GERARDO CAMACHO PONCE | Q64: 767 | R64: =H64&" Y "&I64 -> RODOLFO MONREAL CIRLOS Y SILVIA GUADALUPE SOLORZANO MONGE | S64: =D64&" "&E64&" DE "&F64 -> 12 MARZO DE 2023 | T64: =J64&" "&K64&" DE "&L64 -> 16 MARZO DE 2024 | U64: 2 | V64: 226 | W64: 451
...

Sheet IMPRESION-BAUTIZMO
A1: 142
B3: 116
C4: =VLOOKUP($A$1,BAUTIZMO!$A$6:$W$201,2,FALSE) -> CHRISTIAN DARIEL RAMOS GALVEZ
C5: =VLOOKUP($A$1,BAUTIZMO!$A$6:$W$201,19,FALSE) -> 19 ABRIL DE 2024 | I5: =VLOOKUP($A$1,BAUTIZMO!$A$6:$W$201,17,FALSE) -> 1623
C6: =VLOOKUP($A$1,BAUTIZMO!$A$6:$W$201,7,FALSE) -> HERMOSILLO, SONORA
A7: Y | C7: =VLOOKUP($A$1,BAUTIZMO!$A$6:$W$201,8,FALSE)&A7&VLOOKUP($A$1,BAUTIZMO!$A$6:$W$201,9,FALSE) -> JESUS ARMANDO RAMOS DORAME Y ANA PAULINA GALVEZ BUSTAMANTE
C8: =VLOOKUP($A$1,BAUTIZMO!$A$6:$W$201,14,FALSE) -> CRISTA ANGELICA RAMOS DORAME
C9: =VLOOKUP($A$1,BAUTIZMO!$A$6:$W$201,15,FALSE) -> MARIA JOSE RAMOS DORAME
E10: =VLOOKUP($A$1,BAUTIZMO!$A$6:$W$201,20,FALSE) -> 6 JUNIO DE 2026
C12: =VLOOKUP($A$1,BAUTIZMO!$A$6:$W$201,21,FALSE) -> 2 | D12: Página | E12: =VLOOKUP($A$1,BAUTIZMO!$A$6:$W$201,22,FALSE) -> 269 | H12: =VLOOKUP($A$1,BAUTIZMO!$A$6:$W$201,23,FALSE) -> 537
C15: PBRO. GERARDO
D16: CAMACHO PONCE

Sheet CATECUMENOS 
A1: CATECUMENOS VIGILIA PASCUAL 03 ABRIL 2021

Sheet IMPRESION-COMUNION (2)
A1: 229
C6: =LOOKUP($A$1,'1ra.COMUNION'!$B$5:C3010) -> DANNA CORONADO OLIVAS
D8: =IF(LOOKUP($A$1,'1ra.COMUNION'!$B$5:D3010)=0," ",LOOKUP($A$1,'1ra.COMUNION'!$B$5:G3010)) -> DANIEL EDUARDO CORONADO MOLINA | I8: =IF(LOOKUP($A$1,'1ra.COMUNION'!$B$5:H3010)=0," ",LOOKUP($A$1,'1ra.COMUNION'!$B$5:H3010)) -> MARTINA OLIVAS BERNAL
H9: =LOOKUP(A1,'1ra.COMUNION'!B5:D3010) -> 1 | K9: =LOOKUP(A1,'1ra.COMUNION'!B5:E3010) -> JUNIO | M9: =LOOKUP(A1,'1ra.COMUNION'!B5:F3010) -> 2024
C12: =LOOKUP($A$1,'1ra.COMUNION'!$B$5:I3010) -> DAVID ENRIQUE CORONADO MOLINA Y MARIA DEL CONSUELO MORA MENESES
I14: =LOOKUP($A$1,'1ra.COMUNION'!$B$5:J3010) -> PBRO. GERARDO CAMACHO PONCE
C20: NOTA: SOLO TECLEAR EN LA COLUMAN A1 EL NUMERO CORRESPONDA EN LA HOJA 1ra.COMUNION
